Workbook

Sheet panics
A1: name | B1: go | C1: curr | D1: fair | E1: RFP | F1: RSP | G1: ratio | H1: fund | I1: techn | J1: i1 | K1: i2 | L1: i3 | M1: score | N1: filter | O1: mena | P1: diff | Q1: gny | R1: r | T1: suppos | U1: abs | V1: mom | W1: diff | X1: gny | Y1: r | AA1: suppos | AB1: abs | AC1: mark | AD1: koko
A2: ISPH | B2: =_xlfn.IFNA(INDEX(bf!B:B,MATCH(A2,bf!A:A,0),1),0) -> 9.44 | C2: =INDEX('اسعار الاسهم'!A:L,MATCH(A2,'اسعار الاسهم'!K:K,0),2) -> 11.27 | E2: 1 | G2: =B2/C2 -> 0.83762201 | H2: =19.1/C2-1 -> 0.69476486 | I2: =13/C2-1 -> 0.15350488 | J2: =1-(_xlfn.RANK.EQ(G2,G:G,)-1)/(COUNTIF(G:G,">0")) -> 0.89583333 | K2: =_xlfn.IFNA(1-(_xlfn.RANK.EQ(H2,H:H,)-1)/(COUNTIF(H:H,">0")),0) -> 0.92857143 | L2: =_xlfn.IFNA(1-(_xlfn.RANK.EQ(I2,I:I,)-1)/(COUNTIF(I:I,">0")),0) -> 0.13333333 | M2: =$AG$2*J2+K2 *$AG$3+L2*$AG$4+$AG$5*E2+$AG$6*F2 -> 2.4252381 | N2: =OR(O2<>"",V2<>"") -> TRUE | O2: 6.45 | P2: =IFERROR(T2-O2,"") -> -0.53 | Q2: =IF(P2<>"",IF(ABS(P2)/T2>0.1,"Gny",""),"") | R2: =IF(P2<>"",ABS(P2)/T2,"") -> 0.089527027 | S2: =_xlfn.NUMBERVALUE(S1)+IF(O2,1,0) -> 1 | T2: {=IF(O2,INDEX($AP$2:$AP$21,S2,1),"")} -> 5.92 | U2: =IF(P2<>"",ABS(P2),"") -> 0.53 | V2: 86 | W2: =IFERROR(AA2-V2,"") -> -0.8 | X2: =IF(W2<>"",IF(ABS(W2)/AA2>0.1,"Gny",""),"") | Y2: =IF(W2<>"",ABS(W2)/AA2,"") -> 0.0093896714 | Z2: =_xlfn.NUMBERVALUE(Z1)+IF(V2,1,0) -> 1 | AA2: {=IF(V2,INDEX($AK$2:$AK$20,Z2,1),"")} -> 85.2 | AB2: =IF(W2<>"",ABS(W2),"") -> 0.8 | AC2: 1 | AD2: 1 | AF2: bf | AG2: 0.8 | AI2: 1 | AJ2: =AM2/AM3+(AM3-1)/2*AM22 -> 85.221053 | AK2: =ROUND(AJ2,1) -> 85.2 | AL2: total | AM2: =1225.5+8.9-20 -> 1214.4 | AN2: 1 | AO2: =AR2/AR3+(AR3-1)/2*AR22 -> 5.9178947 | AP2: =ROUND(AO2,2) -> 5.92 | AQ2: total | AR2: =84.33 -> 84.33
A3: HRHO | B3: =_xlfn.IFNA(INDEX(bf!B:B,MATCH(A3,bf!A:A,0),1),0) -> 21.69 | C3: =INDEX('اسعار الاسهم'!A:L,MATCH(A3,'اسعار الاسهم'!K:K,0),2) -> 26.32 | G3: =B3/C3 -> 0.82408815 | H3: =39.4/C3-1 -> 0.49696049 | I3: =38/C3-1 -> 0.443769 | J3: =1-(_xlfn.RANK.EQ(G3,G:G,)-1)/(COUNTIF(G:G,">0")) -> 0.83333333 | K3: =_xlfn.IFNA(1-(_xlfn.RANK.EQ(H3,H:H,)-1)/(COUNTIF(H:H,">0")),0) -> 0.64285714 | L3: =_xlfn.IFNA(1-(_xlfn.RANK.EQ(I3,I:I,)-1)/(COUNTIF(I:I,">0")),0) -> 0.8 | M3: =$AG$2*J3+K3 *$AG$3+L3*$AG$4+$AG$5*E3+$AG$6*F3 -> 1.7895238 | N3: =OR(O3<>"",V3<>"") -> TRUE | O3: 5.96 | P3: =IFERROR(T3-O3,"") -> -0.21 | Q3: =IF(P3<>"",IF(ABS(P3)/T3>0.1,"Gny",""),"") | R3: =IF(P3<>"",ABS(P3)/T3,"") -> 0.036521739 | S3: =_xlfn.NUMBERVALUE(S2)+IF(O3,1,0) -> 2 | T3: {=IF(O3,INDEX($AP$2:$AP$21,S3,1),"")} -> 5.75 | U3: =IF(P3<>"",ABS(P3),"") -> 0.21 | V3: 88.1 | W3: =IFERROR(AA3-V3,"") -> -5.2 | X3: =IF(W3<>"",IF(ABS(W3)/AA3>0.1,"Gny",""),"") | Y3: =IF(W3<>"",ABS(W3)/AA3,"") -> 0.062726176 | Z3: =_xlfn.NUMBERVALUE(Z2)+IF(V3,1,0) -> 2 | AA3: {=IF(V3,INDEX($AK$2:$AK$20,Z3,1),"")} -> 82.9 | AB3: =IF(W3<>"",ABS(W3),"") -> 5.2 | AC3: 1 | AF3: funda | AG3: 1 | AI3: 2 | AJ3: =AJ2-$AM$22 -> 82.853801 | AK3: =ROUND(AJ3,1) -> 82.9 | AL3: count | AM3: 19 | AN3: 2 | AO3: =AO2-$AR$22 -> 5.7535088 | AP3: =ROUND(AO3,2) -> 5.75 | AQ3: count | AR3: 19
A4: ORHD | B4: =_xlfn.IFNA(INDEX(bf!B:B,MATCH(A4,bf!A:A,0),1),0) -> 29.41 | C4: =INDEX('اسعار الاسهم'!A:L,MATCH(A4,'اسعار الاسهم'!K:K,0),2) -> 34.55 | E4: 1 | G4: =B4/C4 -> 0.8512301 | H4: =43/C4-1 -> 0.24457308 | J4: =1-(_xlfn.RANK.EQ(G4,G:G,)-1)/(COUNTIF(G:G,">0")) -> 0.91666667 | K4: =_xlfn.IFNA(1-(_xlfn.RANK.EQ(H4,H:H,)-1)/(COUNTIF(H:H,">0")),0) -> 0.28571429 | L4: =_xlfn.IFNA(1-(_xlfn.RANK.EQ(I4,I:I,)-1)/(COUNTIF(I:I,">0")),0) -> 0 | M4: =$AG$2*J4+K4 *$AG$3+L4*$AG$4+$AG$5*E4+$AG$6*F4 -> 1.7190476 | N4: =OR(O4<>"",V4<>"") -> TRUE | O4: 5.89 | P4: =IFERROR(T4-O4,"") -> -0.3 | Q4: =IF(P4<>"",IF(ABS(P4)/T4>0.1,"Gny",""),"") | R4: =IF(P4<>"",ABS(P4)/T4,"") -> 0.053667263 | S4: =_xlfn.NUMBERVALUE(S3)+IF(O4,1,0) -> 3 | T4: {=IF(O4,INDEX($AP$2:$AP$21,S4,1),"")} -> 5.59 | U4: =IF(P4<>"",ABS(P4),"") -> 0.3 | V4: 87.2 | W4: =IFERROR(AA4-V4,"") -> -6.7 | X4: =IF(W4<>"",IF(ABS(W4)/AA4>0.1,"Gny",""),"") | Y4: =IF(W4<>"",ABS(W4)/AA4,"") -> 0.083229814 | Z4: =_xlfn.NUMBERVALUE(Z3)+IF(V4,1,0) -> 3 | AA4: {=IF(V4,INDEX($AK$2:$AK$20,Z4,1),"")} -> 80.5 | AB4: =IF(W4<>"",ABS(W4),"") -> 6.7 | AC4: 1 | AD4: 1 | AF4: techn | AG4: 0.6 | AI4: 3 | AJ4: =AJ3-$AM$22 -> 80.48655 | AK4: =ROUND(AJ4,1) -> 80.5 | AL4: factor | AM4: =IF(NOW()>DATE(2026,6,5),0.54, IF(NOW()>DATE(2026,6,3),0.53, IF(NOW()>DATE(2026,5,29),0.52, IF(NOW()>DATE(2026,5,27),0.51, IF(NOW()>DATE(2026,5,22),0.5, 0.49))))) -> 0.5 | AN4: 3 | AO4: =AO3-$AR$22 -> 5.5891228 | AP4: =ROUND(AO4,2) -> 5.59 | AQ4: factor | AR4: 0.5
A5: ORAS | B5: =_xlfn.IFNA(INDEX(bf!B:B,MATCH(A5,bf!A:A,0),1),0) -> 0 | C5: =INDEX('اسعار الاسهم'!A:L,MATCH(A5,'اسعار الاسهم'!K:K,0),2) -> 708.01 | E5: 1 | F5: 0.92 | G5: =B5/C5 -> 0 | H5: =890/C5-1 -> 0.25704439 | J5: =1-(_xlfn.RANK.EQ(G5,G:G,)-1)/(COUNTIF(G:G,">0")) -> 0 | K5: =_xlfn.IFNA(1-(_xlfn.RANK.EQ(H5,H:H,)-1)/(COUNTIF(H:H,">0")),0) -> 0.35714286 | L5: =_xlfn.IFNA(1-(_xlfn.RANK.EQ(I5,I:I,)-1)/(COUNTIF(I:I,">0")),0) -> 0 | M5: =$AG$2*J5+K5 *$AG$3+L5*$AG$4+$AG$5*E5+$AG$6*F5 -> 1.7011429 | N5: =OR(O5<>"",V5<>"") -> TRUE | O5: 5.76 | P5: =IFERROR(T5-O5,"") -> -0.34 | Q5: =IF(P5<>"",IF(ABS(P5)/T5>0.1,"Gny",""),"") | R5: =IF(P5<>"",ABS(P5)/T5,"") -> 0.062730627 | S5: =_xlfn.NUMBERVALUE(S4)+IF(O5,1,0) -> 4 | T5: {=IF(O5,INDEX($AP$2:$AP$21,S5,1),"")} -> 5.42 | U5: =IF(P5<>"",ABS(P5),"") -> 0.34 | V5: 84 | W5: =IFERROR(AA5-V5,"") -> -5.9 | X5: =IF(W5<>"",IF(ABS(W5)/AA5>0.1,"Gny",""),"") | Y5: =IF(W5<>"",ABS(W5)/AA5,"") -> 0.075544174 | Z5: =_xlfn.NUMBERVALUE(Z4)+IF(V5,1,0) -> 4 | AA5: {=IF(V5,INDEX($AK$2:$AK$20,Z5,1),"")} -> 78.1 | AB5: =IF(W5<>"",ABS(W5),"") -> 5.9 | AC5: 1 | AD5: 1 | AF5: RFP | AG5: 0.7 | AI5: 4 | AJ5: =AJ4-$AM$22 -> 78.119298 | AK5: =ROUND(AJ5,1) -> 78.1 | AL5: alpha | AM5: =(AM3-1)/2 -> 9 | AN5: 4 | AO5: =AO4-$AR$22 -> 5.4247368 | AP5: =ROUND(AO5,2) -> 5.42 | AQ5: alpha | AR5: =(AR3-1)/2 -> 9
A6: DSCW | B6: =_xlfn.IFNA(INDEX(bf!B:B,MATCH(A6,bf!A:A,0),1),0) -> 0 | C6: =INDEX('اسعار الاسهم'!A:L,MATCH(A6,'اسعار الاسهم'!K:K,0),2) -> 1.74 | E6: 1 | G6: =B6/C6 -> 0 | H6: =3.2/C6-1 -> 0.83908046 | J6: =1-(_xlfn.RANK.EQ(G6,G:G,)-1)/(COUNTIF(G:G,">0")) -> 0 | K6: =_xlfn.IFNA(1-(_xlfn.RANK.EQ(H6,H:H,)-1)/(COUNTIF(H:H,">0")),0) -> 1 | L6: =_xlfn.IFNA(1-(_xlfn.RANK.EQ(I6,I:I,)-1)/(COUNTIF(I:I,">0")),0) -> 0 | M6: =$AG$2*J6+K6 *$AG$3+L6*$AG$4+$AG$5*E6+$AG$6*F6 -> 1.7 | N6: =OR(O6<>"",V6<>"") -> TRUE | O6: 5.19 | P6: =IFERROR(T6-O6,"") -> 0.07 | Q6: =IF(P6<>"",IF(ABS(P6)/T6>0.1,"Gny",""),"") | R6: =IF(P6<>"",ABS(P6)/T6,"") -> 0.013307985 | S6: =_xlfn.NUMBERVALUE(S5)+IF(O6,1,0) -> 5 | T6: {=IF(O6,INDEX($AP$2:$AP$21,S6,1),"")} -> 5.26 | U6: =IF(P6<>"",ABS(P6),"") -> 0.07 | V6: 83.2 | W6: =IFERROR(AA6-V6,"") -> -7.4 | X6: =IF(W6<>"",IF(ABS(W6)/AA6>0.1,"Gny",""),"") | Y6: =IF(W6<>"",ABS(W6)/AA6,"") -> 0.09762533 | Z6: =_xlfn.NUMBERVALUE(Z5)+IF(V6,1,0) -> 5 | AA6: {=IF(V6,INDEX($AK$2:$AK$20,Z6,1),"")} -> 75.8 | AB6: =IF(W6<>"",ABS(W6),"") -> 7.4 | AC6: 1 | AF6: RSP | AG6: 0.7 | AI6: 5 | AJ6: =AJ5-$AM$22 -> 75.752047 | AK6: =ROUND(AJ6,1) -> 75.8 | AM6: =SUM(AB1:AB13)+SUM(AB15:AB180) -> 94.9 | AN6: 5 | AO6: =AO5-$AR$22 -> 5.2603509 | AP6: =ROUND(AO6,2) -> 5.26
A7: OCDI | B7: =_xlfn.IFNA(INDEX(bf!B:B,MATCH(A7,bf!A:A,0),1),0) -> 21.88 | C7: =INDEX('اسعار الاسهم'!A:L,MATCH(A7,'اسعار الاسهم'!K:K,0),2) -> 20.7 | F7: 0.94 | G7: =B7/C7 -> 1.0570048 | J7: =1-(_xlfn.RANK.EQ(G7,G:G,)-1)/(COUNTIF(G:G,">0")) -> 1 | K7: =_xlfn.IFNA(1-(_xlfn.RANK.EQ(H7,H:H,)-1)/(COUNTIF(H:H,">0")),0) -> 0 | L7: =_xlfn.IFNA(1-(_xlfn.RANK.EQ(I7,I:I,)-1)/(COUNTIF(I:I,">0")),0) -> 0 | M7: =$AG$2*J7+K7 *$AG$3+L7*$AG$4+$AG$5*E7+$AG$6*F7 -> 1.458 | N7: =OR(O7<>"",V7<>"") -> TRUE | O7: 4.97 | P7: =IFERROR(T7-O7,"") -> 0.13 | Q7: =IF(P7<>"",IF(ABS(P7)/T7>0.1,"Gny",""),"") | R7: =IF(P7<>"",ABS(P7)/T7,"") -> 0.025490196 | S7: =_xlfn.NUMBERVALUE(S6)+IF(O7,1,0) -> 6 | T7: {=IF(O7,INDEX($AP$2:$AP$21,S7,1),"")} -> 5.1 | U7: =IF(P7<>"",ABS(P7),"") -> 0.13 | V7: 74.3 | W7: =IFERROR(AA7-V7,"") -> -0.9 | X7: =IF(W7<>"",IF(ABS(W7)/AA7>0.1,"Gny",""),"") | Y7: =IF(W7<>"",ABS(W7)/AA7,"") -> 0.01226158 | Z7: =_xlfn.NUMBERVALUE(Z6)+IF(V7,1,0) -> 6 | AA7: {=IF(V7,INDEX($AK$2:$AK$20,Z7,1),"")} -> 73.4 | AB7: =IF(W7<>"",ABS(W7),"") -> 0.9 | AC7: 1 | AD7: 1 | AI7: 6 | AJ7: =AJ6-$AM$22 -> 73.384795 | AK7: =ROUND(AJ7,1) -> 73.4 | AN7: 6 | AO7: =AO6-$AR$22 -> 5.0959649 | AP7: =ROUND(AO7,2) -> 5.1
A8: RAYA | B8: =_xlfn.IFNA(INDEX(bf!B:B,MATCH(A8,bf!A:A,0),1),0) -> 0 | C8: =INDEX('اسعار الاسهم'!A:L,MATCH(A8,'اسعار الاسهم'!K:K,0),2) -> 7.15 | E8: 1 | G8: =B8/C8 -> 0 | H8: =10.8/C8-1 -> 0.51048951 | J8: =1-(_xlfn.RANK.EQ(G8,G:G,)-1)/(COUNTIF(G:G,">0")) -> 0 | K8: =_xlfn.IFNA(1-(_xlfn.RANK.EQ(H8,H:H,)-1)/(COUNTIF(H:H,">0")),0) -> 0.71428571 | L8: =_xlfn.IFNA(1-(_xlfn.RANK.EQ(I8,I:I,)-1)/(COUNTIF(I:I,">0")),0) -> 0 | M8: =$AG$2*J8+K8 *$AG$3+L8*$AG$4+$AG$5*E8+$AG$6*F8 -> 1.4142857 | N8: =OR(O8<>"",V8<>"") -> TRUE | O8: 4.83 | P8: =IFERROR(T8-O8,"") -> 0.1 | Q8: =IF(P8<>"",IF(ABS(P8)/T8>0.1,"Gny",""),"") | R8: =IF(P8<>"",ABS(P8)/T8,"") -> 0.020283976 | S8: =_xlfn.NUMBERVALUE(S7)+IF(O8,1,0) -> 7 | T8: {=IF(O8,INDEX($AP$2:$AP$21,S8,1),"")} -> 4.93 | U8: =IF(P8<>"",ABS(P8),"") -> 0.1 | V8: 71.9 | W8: =IFERROR(AA8-V8,"") -> -0.9 | X8: =IF(W8<>"",IF(ABS(W8)/AA8>0.1,"Gny",""),"") | Y8: =IF(W8<>"",ABS(W8)/AA8,"") -> 0.012676056 | Z8: =_xlfn.NUMBERVALUE(Z7)+IF(V8,1,0) -> 7 | AA8: {=IF(V8,INDEX($AK$2:$AK$20,Z8,1),"")} -> 71 | AB8: =IF(W8<>"",ABS(W8),"") -> 0.9 | AI8: 7 | AJ8: =AJ7-$AM$22 -> 71.017544 | AK8: =ROUND(AJ8,1) -> 71 | AN8: 7 | AO8: =AO7-$AR$22 -> 4.9315789 | AP8: =ROUND(AO8,2) -> 4.93
A9: MTIE | B9: =_xlfn.IFNA(INDEX(bf!B:B,MATCH(A9,bf!A:A,0),1),0) -> 6.8 | C9: =INDEX('اسعار الاسهم'!A:L,MATCH(A9,'اسعار الاسهم'!K:K,0),2) -> 8.79 | F9: 0.96 | G9: =B9/C9 -> 0.77360637 | J9: =1-(_xlfn.RANK.EQ(G9,G:G,)-1)/(COUNTIF(G:G,">0")) -> 0.77083333 | K9: =_xlfn.IFNA(1-(_xlfn.RANK.EQ(H9,H:H,)-1)/(COUNTIF(H:H,">0")),0) -> 0 | L9: =_xlfn.IFNA(1-(_xlfn.RANK.EQ(I9,I:I,)-1)/(COUNTIF(I:I,">0")),0) -> 0 | M9: =$AG$2*J9+K9 *$AG$3+L9*$AG$4+$AG$5*E9+$AG$6*F9 -> 1.2886667 | N9: =OR(O9<>"",V9<>"") -> FALSE | P9: =IFERROR(T9-O9,"") | Q9: =IF(P9<>"",IF(ABS(P9)/T9>0.1,"Gny",""),"") | R9: =IF(P9<>"",ABS(P9)/T9,"") | S9: =_xlfn.NUMBERVALUE(S8)+IF(O9,1,0) -> 7 | T9: {=IF(O9,INDEX($AP$2:$AP$21,S9,1),"")} | U9: =IF(P9<>"",ABS(P9),"") | W9: =IFERROR(AA9-V9,"") | X9: =IF(W9<>"",IF(ABS(W9)/AA9>0.1,"Gny",""),"") | Y9: =IF(W9<>"",ABS(W9)/AA9,"") | Z9: =_xlfn.NUMBERVALUE(Z8)+IF(V9,1,0) -> 7 | AA9: {=IF(V9,INDEX($AK$2:$AK$20,Z9,1),"")} | AB9: =IF(W9<>"",ABS(W9),"") | AI9: 8 | AJ9: =AJ8-$AM$22 -> 68.650292 | AK9: =ROUND(AJ9,1) -> 68.7 | AN9: 8 | AO9: =AO8-$AR$22 -> 4.767193 | AP9: =ROUND(AO9,2) -> 4.77
A10: TMGH | B10: =_xlfn.IFNA(INDEX(bf!B:B,MATCH(A10,bf!A:A,0),1),0) -> 0 | C10: =INDEX('اسعار الاسهم'!A:L,MATCH(A10,'اسعار الاسهم'!K:K,0),2) -> 99.48 | E10: 1 | F10: 0.84 | G10: =B10/C10 -> 0 | J10: =1-(_xlfn.RANK.EQ(G10,G:G,)-1)/(COUNTIF(G:G,">0")) -> 0 | K10: =_xlfn.IFNA(1-(_xlfn.RANK.EQ(H10,H:H,)-1)/(COUNTIF(H:H,">0")),0) -> 0 | L10: =_xlfn.IFNA(1-(_xlfn.RANK.EQ(I10,I:I,)-1)/(COUNTIF(I:I,">0")),0) -> 0 | M10: =$AG$2*J10+K10 *$AG$3+L10*$AG$4+$AG$5*E10+$AG$6*F10 -> 1.288 | N10: =OR(O10<>"",V10<>"") -> TRUE | O10: 4.75 | P10: =IFERROR(T10-O10,"") -> 0.02 | Q10: =IF(P10<>"",IF(ABS(P10)/T10>0.1,"Gny",""),"") | R10: =IF(P10<>"",ABS(P10)/T10,"") -> 0.0041928721 | S10: =_xlfn.NUMBERVALUE(S9)+IF(O10,1,0) -> 8 | T10: {=IF(O10,INDEX($AP$2:$AP$21,S10,1),"")} -> 4.77 | U10: =IF(P10<>"",ABS(P10),"") -> 0.02 | V10: 75.3 | W10: =IFERROR(AA10-V10,"") -> -6.6 | X10: =IF(W10<>"",IF(ABS(W10)/AA10>0.1,"Gny",""),"") | Y10: =IF(W10<>"",ABS(W10)/AA10,"") -> 0.096069869 | Z10: =_xlfn.NUMBERVALUE(Z9)+IF(V10,1,0) -> 8 | AA10: {=IF(V10,INDEX($AK$2:$AK$20,Z10,1),"")} -> 68.7 | AB10: =IF(W10<>"",ABS(W10),"") -> 6.6 | AC10: 1 | AD10: 1 | AI10: 9 | AJ10: =AJ9-$AM$22 -> 66.283041 | AK10: =ROUND(AJ10,1) -> 66.3 | AN10: 9 | AO10: =AO9-$AR$22 -> 4.602807 | AP10: =ROUND(AO10,2) -> 4.6
A11: ORWE | B11: =_xlfn.IFNA(INDEX(bf!B:B,MATCH(A11,bf!A:A,0),1),0) -> 11.06 | C11: =INDEX('اسعار الاسهم'!A:L,MATCH(A11,'اسعار الاسهم'!K:K,0),2) -> 21.84 | F11: 0.9 | G11: =B11/C11 -> 0.50641026 | I11: =30.5/C11-1 -> 0.39652015 | J11: =1-(_xlfn.RANK.EQ(G11,G:G,)-1)/(COUNTIF(G:G,">0")) -> 0.3125 | K11: =_xlfn.IFNA(1-(_xlfn.RANK.EQ(H11,H:H,)-1)/(COUNTIF(H:H,">0")),0) -> 0 | L11: =_xlfn.IFNA(1-(_xlfn.RANK.EQ(I11,I:I,)-1)/(COUNTIF(I:I,">0")),0) -> 0.66666667 | M11: =$AG$2*J11+K11 *$AG$3+L11*$AG$4+$AG$5*E11+$AG$6*F11 -> 1.28 | N11: =OR(O11<>"",V11<>"") -> FALSE | P11: =IFERROR(T11-O11,"") | Q11: =IF(P11<>"",IF(ABS(P11)/T11>0.1,"Gny",""),"") | R11: =IF(P11<>"",ABS(P11)/T11,"") | S11: =_xlfn.NUMBERVALUE(S10)+IF(O11,1,0) -> 8 | T11: {=IF(O11,INDEX($AP$2:$AP$21,S11,1),"")} | U11: =IF(P11<>"",ABS(P11),"") | W11: =IFERROR(AA11-V11,"") | X11: =IF(W11<>"",IF(ABS(W11)/AA11>0.1,"Gny",""),"") | Y11: =IF(W11<>"",ABS(W11)/AA11,"") | Z11: =_xlfn.NUMBERVALUE(Z10)+IF(V11,1,0) -> 8 | AA11: {=IF(V11,INDEX($AK$2:$AK$20,Z11,1),"")} | AB11: =IF(W11<>"",ABS(W11),"") | AI11: 10 | AJ11: =AJ10-$AM$22 -> 63.915789 | AK11: =ROUND(AJ11,1) -> 63.9 | AN11: 10 | AO11: =AO10-$AR$22 -> 4.4384211 | AP11: =ROUND(AO11,2) -> 4.44
A12: AMER | B12: =_xlfn.IFNA(INDEX(bf!B:B,MATCH(A12,bf!A:A,0),1),0) -> 1.67 | C12: =INDEX('اسعار الاسهم'!A:L,MATCH(A12,'اسعار الاسهم'!K:K,0),2) -> 2.57 | F12: 1 | G12: =B12/C12 -> 0.64980545 | J12: =1-(_xlfn.RANK.EQ(G12,G:G,)-1)/(COUNTIF(G:G,">0")) -> 0.60416667 | K12: =_xlfn.IFNA(1-(_xlfn.RANK.EQ(H12,H:H,)-1)/(COUNTIF(H:H,">0")),0) -> 0 | L12: =_xlfn.IFNA(1-(_xlfn.RANK.EQ(I12,I:I,)-1)/(COUNTIF(I:I,">0")),0) -> 0 | M12: =$AG$2*J12+K12 *$AG$3+L12*$AG$4+$AG$5*E12+$AG$6*F12 -> 1.1833333 | N12: =OR(O12<>"",V12<>"") -> TRUE | P12: =IFERROR(T12-O12,"") | Q12: =IF(P12<>"",IF(ABS(P12)/T12>0.1,"Gny",""),"") | R12: =IF(P12<>"",ABS(P12)/T12,"") | S12: =_xlfn.NUMBERVALUE(S11)+IF(O12,1,0) -> 8 | T12: {=IF(O12,INDEX($AP$2:$AP$21,S12,1),"")} | U12: =IF(P12<>"",ABS(P12),"") | V12: 68.1 | W12: =IFERROR(AA12-V12,"") -> -1.8 | X12: =IF(W12<>"",IF(ABS(W12)/AA12>0.1,"Gny",""),"") | Y12: =IF(W12<>"",ABS(W12)/AA12,"") -> 0.027149321 | Z12: =_xlfn.NUMBERVALUE(Z11)+IF(V12,1,0) -> 9 | AA12: {=IF(V12,INDEX($AK$2:$AK$20,Z12,1),"")} -> 66.3 | AB12: =IF(W12<>"",ABS(W12),"") -> 1.8 | AC12: 1 | AI12: 11 | AJ12: =AJ11-$AM$22 -> 61.548538 | AK12: =ROUND(AJ12,1) -> 61.5 | AN12: 11 | AO12: =AO11-$AR$22 -> 4.2740351 | AP12: =ROUND(AO12,2) -> 4.27
A13: SAUD | B13: =_xlfn.IFNA(INDEX(bf!B:B,MATCH(A13,bf!A:A,0),1),0) -> 14.09 | C13: =INDEX('اسعار الاسهم'!A:L,MATCH(A13,'اسعار الاسهم'!K:K,0),2) -> 22.19 | E13: 1 | G13: =B13/C13 -> 0.63497071 | J13: =1-(_xlfn.RANK.EQ(G13,G:G,)-1)/(COUNTIF(G:G,">0")) -> 0.54166667 | K13: =_xlfn.IFNA(1-(_xlfn.RANK.EQ(H13,H:H,)-1)/(COUNTIF(H:H,">0")),0) -> 0 | L13: =_xlfn.IFNA(1-(_xlfn.RANK.EQ(I13,I:I,)-1)/(COUNTIF(I:I,">0")),0) -> 0 | M13: =$AG$2*J13+K13 *$AG$3+L13*$AG$4+$AG$5*E13+$AG$6*F13 -> 1.1333333 | N13: =OR(O13<>"",V13<>"") -> TRUE | O13: 4.62 | P13: =IFERROR(T13-O13,"") -> -0.02 | Q13: =IF(P13<>"",IF(ABS(P13)/T13>0.1,"Gny",""),"") | R13: =IF(P13<>"",ABS(P13)/T13,"") -> 0.0043478261 | S13: =_xlfn.NUMBERVALUE(S12)+IF(O13,1,0) -> 9 | T13: {=IF(O13,INDEX($AP$2:$AP$21,S13,1),"")} -> 4.6 | U13: =IF(P13<>"",ABS(P13),"") -> 0.02 | V13: 70.3 | W13: =IFERROR(AA13-V13,"") -> -6.4 | X13: =IF(W13<>"",IF(ABS(W13)/AA13>0.1,"Gny",""),"") -> Gny | Y13: =IF(W13<>"",ABS(W13)/AA13,"") -> 0.10015649 | Z13: =_xlfn.NUMBERVALUE(Z12)+IF(V13,1,0) -> 10 | AA13: {=IF(V13,INDEX($AK$2:$AK$20,Z13,1),"")} -> 63.9 | AB13: =IF(W13<>"",ABS(W13),"") -> 6.4 | AI13: 12 | AJ13: =AJ12-$AM$22 -> 59.181287 | AK13: =ROUND(AJ13,1) -> 59.2 | AN13: 12 | AO13: =AO12-$AR$22 -> 4.1096491 | AP13: =ROUND(AO13,2) -> 4.11
A14: TAQA | B14: =_xlfn.IFNA(INDEX(bf!B:B,MATCH(A14,bf!A:A,0),1),0) -> 0 | C14: =INDEX('اسعار الاسهم'!A:L,MATCH(A14,'اسعار الاسهم'!K:K,0),2) -> 13.19 | G14: =B14/C14 -> 0 | H14: =20.2/C14-1 -> 0.53146323 | I14: =17.5/C14-1 -> 0.3267627 | J14: =1-(_xlfn.RANK.EQ(G14,G:G,)-1)/(COUNTIF(G:G,">0")) -> 0 | K14: =_xlfn.IFNA(1-(_xlfn.RANK.EQ(H14,H:H,)-1)/(COUNTIF(H:H,">0")),0) -> 0.78571429 | L14: =_xlfn.IFNA(1-(_xlfn.RANK.EQ(I14,I:I,)-1)/(COUNTIF(I:I,">0")),0) -> 0.53333333 | M14: =$AG$2*J14+K14 *$AG$3+L14*$AG$4+$AG$5*E14+$AG$6*F14 -> 1.1057143 | N14: =OR(O14<>"",V14<>"") -> FALSE | P14: =IFERROR(T14-O14,"") | Q14: =IF(P14<>"",IF(ABS(P14)/T14>0.1,"Gny",""),"") | R14: =IF(P14<>"",ABS(P14)/T14,"") | S14: =_xlfn.NUMBERVALUE(S13)+IF(O14,1,0) -> 9 | T14: {=IF(O14,INDEX($AP$2:$AP$21,S14,1),"")} | U14: =IF(P14<>"",ABS(P14),"") | W14: =IFERROR(AA14-V14,"") | X14: =IF(W14<>"",IF(ABS(W14)/AA14>0.1,"Gny",""),"") | Y14: =IF(W14<>"",ABS(W14)/AA14,"") | Z14: =_xlfn.NUMBERVALUE(Z13)+IF(V14,1,0) -> 10 | AA14: {=IF(V14,INDEX($AK$2:$AK$20,Z14,1),"")} | AB14: =IF(W14<>"",ABS(W14),"") | AI14: 13 | AJ14: =AJ13-$AM$22 -> 56.814035 | AK14: =ROUND(AJ14,1) -> 56.8 | AN14: 13 | AO14: =AO13-$AR$22 -> 3.9452632 | AP14: =ROUND(AO14,2) -> 3.95
A15: EFIH | B15: =_xlfn.IFNA(INDEX(bf!B:B,MATCH(A15,bf!A:A,0),1),0) -> 16.07 | C15: =INDEX('اسعار الاسهم'!A:L,MATCH(A15,'اسعار الاسهم'!K:K,0),2) -> 21.76 | G15: =B15/C15 -> 0.73851103 | H15: =30.1/C15-1 -> 0.38327206 | J15: =1-(_xlfn.RANK.EQ(G15,G:G,)-1)/(COUNTIF(G:G,">0")) -> 0.72916667 | K15: =_xlfn.IFNA(1-(_xlfn.RANK.EQ(H15,H:H,)-1)/(COUNTIF(H:H,">0")),0) -> 0.5 | L15: =_xlfn.IFNA(1-(_xlfn.RANK.EQ(I15,I:I,)-1)/(COUNTIF(I:I,">0")),0) -> 0 | M15: =$AG$2*J15+K15 *$AG$3+L15*$AG$4+$AG$5*E15+$AG$6*F15 -> 1.0833333 | N15: =OR(O15<>"",V15<>"") -> TRUE | O15: 2.55 | P15: =IFERROR(T15-O15,"") -> 1.89 | Q15: =IF(P15<>"",IF(ABS(P15)/T15>0.1,"Gny",""),"") -> Gny | R15: =IF(P15<>"",ABS(P15)/T15,"") -> 0.42567568 | S15: =_xlfn.NUMBERVALUE(S14)+IF(O15,1,0) -> 10 | T15: {=IF(O15,INDEX($AP$2:$AP$21,S15,1),"")} -> 4.44 | U15: =IF(P15<>"",ABS(P15),"") -> 1.89 | V15: 23.2 | W15: =IFERROR(AA15-V15,"") -> 38.3 | X15: =IF(W15<>"",IF(ABS(W15)/AA15>0.1,"Gny",""),"") -> Gny | Y15: =IF(W15<>"",ABS(W15)/AA15,"") -> 0.62276423 | Z15: =_xlfn.NUMBERVALUE(Z14)+IF(V15,1,0) -> 11 | AA15: {=IF(V15,INDEX($AK$2:$AK$20,Z15,1),"")} -> 61.5 | AB15: =IF(W15<>"",ABS(W15),"") -> 38.3 | AI15: 14 | AJ15: =AJ14-$AM$22 -> 54.446784 | AK15: =ROUND(AJ15,1) -> 54.4 | AN15: 14 | AO15: =AO14-$AR$22 -> 3.7808772 | AP15: =ROUND(AO15,2) -> 3.78
A16: EHDR | B16: =_xlfn.IFNA(INDEX(bf!B:B,MATCH(A16,bf!A:A,0),1),0) -> 1.71 | C16: =INDEX('اسعار الاسهم'!A:L,MATCH(A16,'اسعار الاسهم'!K:K,0),2) -> 2.26 | G16: =B16/C16 -> 0.75663717 | I16: =3.2/C16-1 -> 0.4159292 | J16: =1-(_xlfn.RANK.EQ(G16,G:G,)-1)/(COUNTIF(G:G,">0")) -> 0.75 | K16: =_xlfn.IFNA(1-(_xlfn.RANK.EQ(H16,H:H,)-1)/(COUNTIF(H:H,">0")),0) -> 0 | L16: =_xlfn.IFNA(1-(_xlfn.RANK.EQ(I16,I:I,)-1)/(COUNTIF(I:I,">0")),0) -> 0.76666667 | M16: =$AG$2*J16+K16 *$AG$3+L16*$AG$4+$AG$5*E16+$AG$6*F16 -> 1.06 | N16: =OR(O16<>"",V16<>"") -> FALSE | P16: =IFERROR(T16-O16,"") | Q16: =IF(P16<>"",IF(ABS(P16)/T16>0.1,"Gny",""),"") | R16: =IF(P16<>"",ABS(P16)/T16,"") | S16: =_xlfn.NUMBERVALUE(S15)+IF(O16,1,0) -> 10 | T16: {=IF(O16,INDEX($AP$2:$AP$21,S16,1),"")} | U16: =IF(P16<>"",ABS(P16),"") | W16: =IFERROR(AA16-V16,"") | X16: =IF(W16<>"",IF(ABS(W16)/AA16>0.1,"Gny",""),"") | Y16: =IF(W16<>"",ABS(W16)/AA16,"") | Z16: =_xlfn.NUMBERVALUE(Z15)+IF(V16,1,0) -> 11 | AA16: {=IF(V16,INDEX($AK$2:$AK$20,Z16,1),"")} | AB16: =IF(W16<>"",ABS(W16),"") | AI16: 15 | AJ16: =AJ15-$AM$22 -> 52.079532 | AK16: =ROUND(AJ16,1) -> 52.1 | AN16: 15 | AO16: =AO15-$AR$22 -> 3.6164912 | AP16: =ROUND(AO16,2) -> 3.62
A17: CLHO | B17: =_xlfn.IFNA(INDEX(bf!B:B,MATCH(A17,bf!A:A,0),1),0) -> 5.96 | C17: =INDEX('اسعار الاسهم'!A:L,MATCH(A17,'اسعار الاسهم'!K:K,0),2) -> 15.19 | E17: 1 | G17: =B17/C17 -> 0.3923634 | H17: =18.9/C17-1 -> 0.24423963 | J17: =1-(_xlfn.RANK.EQ(G17,G:G,)-1)/(COUNTIF(G:G,">0")) -> 0.125 | K17: =_xlfn.IFNA(1-(_xlfn.RANK.EQ(H17,H:H,)-1)/(COUNTIF(H:H,">0")),0) -> 0.21428571 | L17: =_xlfn.IFNA(1-(_xlfn.RANK.EQ(I17,I:I,)-1)/(COUNTIF(I:I,">0")),0) -> 0 | M17: =$AG$2*J17+K17 *$AG$3+L17*$AG$4+$AG$5*E17+$AG$6*F17 -> 1.0142857 | N17: =OR(O17<>"",V17<>"") -> TRUE | O17: 3.92 | P17: =IFERROR(T17-O17,"") -> 0.35 | Q17: =IF(P17<>"",IF(ABS(P17)/T17>0.1,"Gny",""),"") | R17: =IF(P17<>"",ABS(P17)/T17,"") -> 0.081967213 | S17: =_xlfn.NUMBERVALUE(S16)+IF(O17,1,0) -> 11 | T17: {=IF(O17,INDEX($AP$2:$AP$21,S17,1),"")} -> 4.27 | U17: =IF(P17<>"",ABS(P17),"") -> 0.35 | V17: 55.6 | W17: =IFERROR(AA17-V17,"") -> 3.6 | X17: =IF(W17<>"",IF(ABS(W17)/AA17>0.1,"Gny",""),"") | Y17: =IF(W17<>"",ABS(W17)/AA17,"") -> 0.060810811 | Z17: =_xlfn.NUMBERVALUE(Z16)+IF(V17,1,0) -> 12 | AA17: {=IF(V17,INDEX($AK$2:$AK$20,Z17,1),"")} -> 59.2 | AB17: =IF(W17<>"",ABS(W17),"") -> 3.6 | AC17: 1 | AI17: 16 | AJ17: =AJ16-$AM$22 -> 49.712281 | AK17: =ROUND(AJ17,1) -> 49.7 | AN17: 16 | AO17: =AO16-$AR$22 -> 3.4521053 | AP17: =ROUND(AO17,2) -> 3.45
A18: ZMID | B18: =_xlfn.IFNA(INDEX(bf!B:B,MATCH(A18,bf!A:A,0),1),0) -> 3.8 | C18: =INDEX('اسعار الاسهم'!A:L,MATCH(A18,'اسعار الاسهم'!K:K,0),2) -> 5.86 | G18: =B18/C18 -> 0.64846416 | I18: =9/C18-1 -> 0.53583618 | J18: =1-(_xlfn.RANK.EQ(G18,G:G,)-1)/(COUNTIF(G:G,">0")) -> 0.58333333 | K18: =_xlfn.IFNA(1-(_xlfn.RANK.EQ(H18,H:H,)-1)/(COUNTIF(H:H,">0")),0) -> 0 | L18: =_xlfn.IFNA(1-(_xlfn.RANK.EQ(I18,I:I,)-1)/(COUNTIF(I:I,">0")),0) -> 0.86666667 | M18: =$AG$2*J18+K18 *$AG$3+L18*$AG$4+$AG$5*E18+$AG$6*F18 -> 0.98666667 | N18: =OR(O18<>"",V18<>"") -> FALSE | P18: =IFERROR(T18-O18,"") | Q18: =IF(P18<>"",IF(ABS(P18)/T18>0.1,"Gny",""),"") | R18: =IF(P18<>"",ABS(P18)/T18,"") | S18: =_xlfn.NUMBERVALUE(S17)+IF(O18,1,0) -> 11 | T18: {=IF(O18,INDEX($AP$2:$AP$21,S18,1),"")} | U18: =IF(P18<>"",ABS(P18),"") | W18: =IFERROR(AA18-V18,"") | X18: =IF(W18<>"",IF(ABS(W18)/AA18>0.1,"Gny",""),"") | Y18: =IF(W18<>"",ABS(W18)/AA18,"") | Z18: =_xlfn.NUMBERVALUE(Z17)+IF(V18,1,0) -> 12 | AA18: {=IF(V18,INDEX($AK$2:$AK$20,Z18,1),"")} | AB18: =IF(W18<>"",ABS(W18),"") | AI18: 17 | AJ18: =AJ17-$AM$22 -> 47.345029 | AK18: =ROUND(AJ18,1) -> 47.3 | AN18: 17 | AO18: =AO17-$AR$22 -> 3.2877193 | AP18: =ROUND(AO18,2) -> 3.29
A19: SWDY | B19: =_xlfn.IFNA(INDEX(bf!B:B,MATCH(A19,bf!A:A,0),1),0) -> 49.17 | C19: =INDEX('اسعار الاسهم'!A:L,MATCH(A19,'اسعار الاسهم'!K:K,0),2) -> 87.9 | F19: 0.86 | G19: =B19/C19 -> 0.55938567 | J19: =1-(_xlfn.RANK.EQ(G19,G:G,)-1)/(COUNTIF(G:G,">0")) -> 0.4375 | K19: =_xlfn.IFNA(1-(_xlfn.RANK.EQ(H19,H:H,)-1)/(COUNTIF(H:H,">0")),0) -> 0 | L19: =_xlfn.IFNA(1-(_xlfn.RANK.EQ(I19,I:I,)-1)/(COUNTIF(I:I,">0")),0) -> 0 | M19: =$AG$2*J19+K19 *$AG$3+L19*$AG$4+$AG$5*E19+$AG$6*F19 -> 0.952 | N19: =OR(O19<>"",V19<>"") -> FALSE | P19: =IFERROR(T19-O19,"") | Q19: =IF(P19<>"",IF(ABS(P19)/T19>0.1,"Gny",""),"") | R19: =IF(P19<>"",ABS(P19)/T19,"") | S19: =_xlfn.NUMBERVALUE(S18)+IF(O19,1,0) -> 11 | T19: {=IF(O19,INDEX($AP$2:$AP$21,S19,1),"")} | U19: =IF(P19<>"",ABS(P19),"") | W19: =IFERROR(AA19-V19,"") | X19: =IF(W19<>"",IF(ABS(W19)/AA19>0.1,"Gny",""),"") | Y19: =IF(W19<>"",ABS(W19)/AA19,"") | Z19: =_xlfn.NUMBERVALUE(Z18)+IF(V19,1,0) -> 12 | AA19: {=IF(V19,INDEX($AK$2:$AK$20,Z19,1),"")} | AB19: =IF(W19<>"",ABS(W19),"") | AI19: 18 | AJ19: =AJ18-$AM$22 -> 44.977778 | AK19: =ROUND(AJ19,1) -> 45 | AN19: 18 | AO19: =AO18-$AR$22 -> 3.1233333 | AP19: =ROUND(AO19,2) -> 3.12
A20: QNBE | B20: =_xlfn.IFNA(INDEX(bf!B:B,MATCH(A20,bf!A:A,0),1),0) -> 50.91 | C20: =INDEX('اسعار الاسهم'!A:L,MATCH(A20,'اسعار الاسهم'!K:K,0),2) -> 53.39 | G20: =B20/C20 -> 0.95354935 | H20: =64/C20-1 -> 0.19872635 | J20: =1-(_xlfn.RANK.EQ(G20,G:G,)-1)/(COUNTIF(G:G,">0")) -> 0.95833333 | K20: =_xlfn.IFNA(1-(_xlfn.RANK.EQ(H20,H:H,)-1)/(COUNTIF(H:H,">0")),0) -> 0.14285714 | L20: =_xlfn.IFNA(1-(_xlfn.RANK.EQ(I20,I:I,)-1)/(COUNTIF(I:I,">0")),0) -> 0 | M20: =$AG$2*J20+K20 *$AG$3+L20*$AG$4+$AG$5*E20+$AG$6*F20 -> 0.90952381 | N20: =OR(O20<>"",V20<>"") -> TRUE | O20: 4.25 | P20: =IFERROR(T20-O20,"") -> -0.14 | Q20: =IF(P20<>"",IF(ABS(P20)/T20>0.1,"Gny",""),"") | R20: =IF(P20<>"",ABS(P20)/T20,"") -> 0.03406326 | S20: =_xlfn.NUMBERVALUE(S19)+IF(O20,1,0) -> 12 | T20: {=IF(O20,INDEX($AP$2:$AP$21,S20,1),"")} -> 4.11 | U20: =IF(P20<>"",ABS(P20),"") -> 0.14 | V20: 57.4 | W20: =IFERROR(AA20-V20,"") -> -0.6 | X20: =IF(W20<>"",IF(ABS(W20)/AA20>0.1,"Gny",""),"") | Y20: =IF(W20<>"",ABS(W20)/AA20,"") -> 0.01056338 | Z20: =_xlfn.NUMBERVALUE(Z19)+IF(V20,1,0) -> 13 | AA20: {=IF(V20,INDEX($AK$2:$AK$20,Z20,1),"")} -> 56.8 | AB20: =IF(W20<>"",ABS(W20),"") -> 0.6 | AC20: 1 | AD20: 1 | AI20: 19 | AJ20: =AJ19-$AM$22 -> 42.610526 | AK20: =ROUND(AJ20,1) -> 42.6 | AN20: 19 | AO20: =AO19-$AR$22 -> 2.9589474 | AP20: =ROUND(AO20,2) -> 2.96
A21: PHDC | B21: =_xlfn.IFNA(INDEX(bf!B:B,MATCH(A21,bf!A:A,0),1),0) -> 7.5 | C21: =INDEX('اسعار الاسهم'!A:L,MATCH(A21,'اسعار الاسهم'!K:K,0),2) -> 13.61 | F21: 0.88 | G21: =B21/C21 -> 0.55106539 | J21: =1-(_xlfn.RANK.EQ(G21,G:G,)-1)/(COUNTIF(G:G,">0")) -> 0.35416667 | K21: =_xlfn.IFNA(1-(_xlfn.RANK.EQ(H21,H:H,)-1)/(COUNTIF(H:H,">0")),0) -> 0 | L21: =_xlfn.IFNA(1-(_xlfn.RANK.EQ(I21,I:I,)-1)/(COUNTIF(I:I,">0")),0) -> 0 | M21: =$AG$2*J21+K21 *$AG$3+L21*$AG$4+$AG$5*E21+$AG$6*F21 -> 0.89933333 | N21: =OR(O21<>"",V21<>"") -> FALSE | P21: =IFERROR(T21-O21,"") | Q21: =IF(P21<>"",IF(ABS(P21)/T21>0.1,"Gny",""),"") | R21: =IF(P21<>"",ABS(P21)/T21,"") | S21: =_xlfn.NUMBERVALUE(S20)+IF(O21,1,0) -> 12 | T21: {=IF(O21,INDEX($AP$2:$AP$21,S21,1),"")} | U21: =IF(P21<>"",ABS(P21),"") | W21: =IFERROR(AA21-V21,"") | X21: =IF(W21<>"",IF(ABS(W21)/AA21>0.1,"Gny",""),"") | Y21: =IF(W21<>"",ABS(W21)/AA21,"") | Z21: =_xlfn.NUMBERVALUE(Z20)+IF(V21,1,0) -> 13 | AA21: {=IF(V21,INDEX($AK$2:$AK$20,Z21,1),"")} | AB21: =IF(W21<>"",ABS(W21),"")
A22: FWRY | B22: =_xlfn.IFNA(INDEX(bf!B:B,MATCH(A22,bf!A:A,0),1),0) -> 16 | C22: =INDEX('اسعار الاسهم'!A:L,MATCH(A22,'اسعار الاسهم'!K:K,0),2) -> 19.32 | G22: =B22/C22 -> 0.82815735 | I22: =23.5/C22-1 -> 0.21635611 | J22: =1-(_xlfn.RANK.EQ(G22,G:G,)-1)/(COUNTIF(G:G,">0")) -> 0.875 | K22: =_xlfn.IFNA(1-(_xlfn.RANK.EQ(H22,H:H,)-1)/(COUNTIF(H:H,">0")),0) -> 0 | L22: =_xlfn.IFNA(1-(_xlfn.RANK.EQ(I22,I:I,)-1)/(COUNTIF(I:I,">0")),0) -> 0.3 | M22: =$AG$2*J22+K22 *$AG$3+L22*$AG$4+$AG$5*E22+$AG$6*F22 -> 0.88 | N22: =OR(O22<>"",V22<>"") -> FALSE | P22: =IFERROR(T22-O22,"") | Q22: =IF(P22<>"",IF(ABS(P22)/T22>0.1,"Gny",""),"") | R22: =IF(P22<>"",ABS(P22)/T22,"") | S22: =_xlfn.NUMBERVALUE(S21)+IF(O22,1,0) -> 12 | T22: {=IF(O22,INDEX($AP$2:$AP$21,S22,1),"")} | U22: =IF(P22<>"",ABS(P22),"") | W22: =IFERROR(AA22-V22,"") | X22: =IF(W22<>"",IF(ABS(W22)/AA22>0.1,"Gny",""),"") | Y22: =IF(W22<>"",ABS(W22)/AA22,"") | Z22: =_xlfn.NUMBERVALUE(Z21)+IF(V22,1,0) -> 13 | AA22: {=IF(V22,INDEX($AK$2:$AK$20,Z22,1),"")} | AB22: =IF(W22<>"",ABS(W22),"") | AM22: =AM2*(1-AM4)/AM3/(AM5+AM4*AM5) -> 2.3672515 | AR22: =AR2*(1-AR4)/AR3/(AR5+AR4*AR5) -> 0.16438596
A23: MPRC | B23: =_xlfn.IFNA(INDEX(bf!B:B,MATCH(A23,bf!A:A,0),1),0) -> 24.88 | C23: =INDEX('اسعار الاسهم'!A:L,MATCH(A23,'اسعار الاسهم'!K:K,0),2) -> 31.55 | G23: =B23/C23 -> 0.78858954 | I23: =40/C23-1 -> 0.26782884 | J23: =1-(_xlfn.RANK.EQ(G23,G:G,)-1)/(COUNTIF(G:G,">0")) -> 0.8125 | K23: =_xlfn.IFNA(1-(_xlfn.RANK.EQ(H23,H:H,)-1)/(COUNTIF(H:H,">0")),0) -> 0 | L23: =_xlfn.IFNA(1-(_xlfn.RANK.EQ(I23,I:I,)-1)/(COUNTIF(I:I,">0")),0) -> 0.36666667 | M23: =$AG$2*J23+K23 *$AG$3+L23*$AG$4+$AG$5*E23+$AG$6*F23 -> 0.87 | N23: =OR(O23<>"",V23<>"") -> FALSE | Q23: =IF(P23<>"",IF(ABS(P23)/T23>0.1,"Gny",""),"") | R23: =IF(P23<>"",ABS(P23)/T23,"") | S23: =_xlfn.NUMBERVALUE(S22)+IF(O23,1,0) -> 12 | U23: =IF(P23<>"",ABS(P23),"") | W23: =IFERROR(AA23-V23,"") | X23: =IF(W23<>"",IF(ABS(W23)/AA23>0.1,"Gny",""),"") | Y23: =IF(W23<>"",ABS(W23)/AA23,"") | Z23: =_xlfn.NUMBERVALUE(Z22)+IF(V23,1,0) -> 13 | AA23: {=IF(V23,INDEX($AK$2:$AK$20,Z23,1),"")} | AB23: =IF(W23<>"",ABS(W23),"") | AD23: 1
A24: BONY | B24: =_xlfn.IFNA(INDEX(bf!B:B,MATCH(A24,bf!A:A,0),1),0) -> 0 | C24: =INDEX('اسعار الاسهم'!A:L,MATCH(A24,'اسعار الاسهم'!K:K,0),2) -> 4.88 | G24: =B24/C24 -> 0 | H24: =7.6/C24-1 -> 0.55737705 | J24: =1-(_xlfn.RANK.EQ(G24,G:G,)-1)/(COUNTIF(G:G,">0")) -> 0 | K24: =_xlfn.IFNA(1-(_xlfn.RANK.EQ(H24,H:H,)-1)/(COUNTIF(H:H,">0")),0) -> 0.85714286 | L24: =_xlfn.IFNA(1-(_xlfn.RANK.EQ(I24,I:I,)-1)/(COUNTIF(I:I,">0")),0) -> 0 | M24: =$AG$2*J24+K24 *$AG$3+L24*$AG$4+$AG$5*E24+$AG$6*F24 -> 0.85714286 | N24: =OR(O24<>"",V24<>"") -> TRUE | O24: 3.82 | P24: =IFERROR(T24-O24,"") -> 0.13 | Q24: =IF(P24<>"",IF(ABS(P24)/T24>0.1,"Gny",""),"") | R24: =IF(P24<>"",ABS(P24)/T24,"") -> 0.032911392 | S24: =_xlfn.NUMBERVALUE(S23)+IF(O24,1,0) -> 13 | T24: {=IF(O24,INDEX($AP$2:$AP$21,S24,1),"")} -> 3.95 | U24: =IF(P24<>"",ABS(P24),"") -> 0.13 | V24: 55.5 | W24: =IFERROR(AA24-V24,"") -> -1.1 | X24: =IF(W24<>"",IF(ABS(W24)/AA24>0.1,"Gny",""),"") | Y24: =IF(W24<>"",ABS(W24)/AA24,"") -> 0.020220588 | Z24: =_xlfn.NUMBERVALUE(Z23)+IF(V24,1,0) -> 14 | AA24: {=IF(V24,INDEX($AK$2:$AK$20,Z24,1),"")} -> 54.4 | AB24: =IF(W24<>"",ABS(W24),"") -> 1.1 | AC24: 1 | AD24: 1
A25: ENGC | B25: =_xlfn.IFNA(INDEX(bf!B:B,MATCH(A25,bf!A:A,0),1),0) -> 20.74 | C25: =INDEX('اسعار الاسهم'!A:L,MATCH(A25,'اسعار الاسهم'!K:K,0),2) -> 32.76 | G25: =B25/C25 -> 0.63308913 | H25: =44/C25-1 -> 0.34310134 | J25: =1-(_xlfn.RANK.EQ(G25,G:G,)-1)/(COUNTIF(G:G,">0")) -> 0.52083333 | K25: =_xlfn.IFNA(1-(_xlfn.RANK.EQ(H25,H:H,)-1)/(COUNTIF(H:H,">0")),0) -> 0.42857143 | L25: =_xlfn.IFNA(1-(_xlfn.RANK.EQ(I25,I:I,)-1)/(COUNTIF(I:I,">0")),0) -> 0 | M25: =$AG$2*J25+K25 *$AG$3+L25*$AG$4+$AG$5*E25+$AG$6*F25 -> 0.8452381 | N25: =OR(O25<>"",V25<>"") -> TRUE | O25: 3.87 | P25: =IFERROR(T25-O25,"") -> -0.09 | Q25: =IF(P25<>"",IF(ABS(P25)/T25>0.1,"Gny",""),"") | R25: =IF(P25<>"",ABS(P25)/T25,"") -> 0.023809524 | S25: =_xlfn.NUMBERVALUE(S24)+IF(O25,1,0) -> 14 | T25: {=IF(O25,INDEX($AP$2:$AP$21,S25,1),"")} -> 3.78 | U25: =IF(P25<>"",ABS(P25),"") -> 0.09 | W25: =IFERROR(AA25-V25,"") | X25: =IF(W25<>"",IF(ABS(W25)/AA25>0.1,"Gny",""),"") | Y25: =IF(W25<>"",ABS(W25)/AA25,"") | Z25: =_xlfn.NUMBERVALUE(Z24)+IF(V25,1,0) -> 14 | AA25: {=IF(V25,INDEX($AK$2:$AK$20,Z25,1),"")} | AB25: =IF(W25<>"",ABS(W25),"")
A26: CIEB | B26: =_xlfn.IFNA(INDEX(bf!B:B,MATCH(A26,bf!A:A,0),1),0) -> 22.46 | C26: =INDEX('اسعار الاسهم'!A:L,MATCH(A26,'اسعار الاسهم'!K:K,0),2) -> 23.41 | G26: =B26/C26 -> 0.95941905 | J26: =1-(_xlfn.RANK.EQ(G26,G:G,)-1)/(COUNTIF(G:G,">0")) -> 0.97916667 | K26: =_xlfn.IFNA(1-(_xlfn.RANK.EQ(H26,H:H,)-1)/(COUNTIF(H:H,">0")),0) -> 0 | L26: =_xlfn.IFNA(1-(_xlfn.RANK.EQ(I26,I:I,)-1)/(COUNTIF(I:I,">0")),0) -> 0 | M26: =$AG$2*J26+K26 *$AG$3+L26*$AG$4+$AG$5*E26+$AG$6*F26 -> 0.78333333 | N26: =OR(O26<>"",V26<>"") -> FALSE | P26: =IFERROR(T26-O26,"") | Q26: =IF(P26<>"",IF(ABS(P26)/T26>0.1,"Gny",""),"") | R26: =IF(P26<>"",ABS(P26)/T26,"") | S26: =_xlfn.NUMBERVALUE(S25)+IF(O26,1,0) -> 14 | T26: {=IF(O26,INDEX($AP$2:$AP$21,S26,1),"")} | U26: =IF(P26<>"",ABS(P26),"") | W26: =IFERROR(AA26-V26,"") | X26: =IF(W26<>"",IF(ABS(W26)/AA26>0.1,"Gny",""),"") | Y26: =IF(W26<>"",ABS(W26)/AA26,"") | Z26: =_xlfn.NUMBERVALUE(Z25)+IF(V26,1,0) -> 14 | AA26: {=IF(V26,INDEX($AK$2:$AK$20,Z26,1),"")} | AB26: =IF(W26<>"",ABS(W26),"")
A27: COMI | B27: =_xlfn.IFNA(INDEX(bf!B:B,MATCH(A27,bf!A:A,0),1),0) -> 115.7 | C27: =INDEX('اسعار الاسهم'!A:L,MATCH(A27,'اسعار الاسهم'!K:K,0),2) -> 132.35 | G27: =B27/C27 -> 0.8741972 | J27: =1-(_xlfn.RANK.EQ(G27,G:G,)-1)/(COUNTIF(G:G,">0")) -> 0.9375 | K27: =_xlfn.IFNA(1-(_xlfn.RANK.EQ(H27,H:H,)-1)/(COUNTIF(H:H,">0")),0) -> 0 | L27: =_xlfn.IFNA(1-(_xlfn.RANK.EQ(I27,I:I,)-1)/(COUNTIF(I:I,">0")),0) -> 0 | M27: =$AG$2*J27+K27 *$AG$3+L27*$AG$4+$AG$5*E27+$AG$6*F27 -> 0.75 | N27: =OR(O27<>"",V27<>"") -> FALSE | P27: =IFERROR(T27-O27,"") | Q27: =IF(P27<>"",IF(ABS(P27)/T27>0.1,"Gny",""),"") | R27: =IF(P27<>"",ABS(P27)/T27,"") | S27: =_xlfn.NUMBERVALUE(S26)+IF(O27,1,0) -> 14 | T27: {=IF(O27,INDEX($AP$2:$AP$21,S27,1),"")} | U27: =IF(P27<>"",ABS(P27),"") | W27: =IFERROR(AA27-V27,"") | X27: =IF(W27<>"",IF(ABS(W27)/AA27>0.1,"Gny",""),"") | Y27: =IF(W27<>"",ABS(W27)/AA27,"") | Z27: =_xlfn.NUMBERVALUE(Z26)+IF(V27,1,0) -> 14 | AA27: {=IF(V27,INDEX($AK$2:$AK$20,Z27,1),"")} | AB27: =IF(W27<>"",ABS(W27),"") | AM27: =SUM(AB:AB)/SUM(V:V)*100 -> 7.743778 | AR27: =SUM(U:U)/SUM(O:O)*100 -> 6.3461768
A28: JUFO | B28: =_xlfn.IFNA(INDEX(bf!B:B,MATCH(A28,bf!A:A,0),1),0) -> 13.06 | C28: =INDEX('اسعار الاسهم'!A:L,MATCH(A28,'اسعار الاسهم'!K:K,0),2) -> 27 | G28: =B28/C28 -> 0.4837037 | I28: =40/C28-1 -> 0.48148148 | J28: =1-(_xlfn.RANK.EQ(G28,G:G,)-1)/(COUNTIF(G:G,">0")) -> 0.27083333 | K28: =_xlfn.IFNA(1-(_xlfn.RANK.EQ(H28,H:H,)-1)/(COUNTIF(H:H,">0")),0) -> 0 | L28: =_xlfn.IFNA(1-(_xlfn.RANK.EQ(I28,I:I,)-1)/(COUNTIF(I:I,">0")),0) -> 0.83333333 | M28: =$AG$2*J28+K28 *$AG$3+L28*$AG$4+$AG$5*E28+$AG$6*F28 -> 0.71666667 | N28: =OR(O28<>"",V28<>"") -> FALSE | P28: =IFERROR(T28-O28,"") | Q28: =IF(P28<>"",IF(ABS(P28)/T28>0.1,"Gny",""),"") | R28: =IF(P28<>"",ABS(P28)/T28,"") | S28: =_xlfn.NUMBERVALUE(S27)+IF(O28,1,0) -> 14 | T28: {=IF(O28,INDEX($AP$2:$AP$21,S28,1),"")} | U28: =IF(P28<>"",ABS(P28),"") | W28: =IFERROR(AA28-V28,"") | X28: =IF(W28<>"",IF(ABS(W28)/AA28>0.1,"Gny",""),"") | Y28: =IF(W28<>"",ABS(W28)/AA28,"") | Z28: =_xlfn.NUMBERVALUE(Z27)+IF(V28,1,0) -> 14 | AA28: {=IF(V28,INDEX($AK$2:$AK$20,Z28,1),"")} | AB28: =IF(W28<>"",ABS(W28),"")
A29: ARCC | B29: =_xlfn.IFNA(INDEX(bf!B:B,MATCH(A29,bf!A:A,0),1),0) -> 0 | C29: =INDEX('اسعار الاسهم'!A:L,MATCH(A29,'اسعار الاسهم'!K:K,0),2) -> 54.2 | E29: 1 | G29: =B29/C29 -> 0 | J29: =1-(_xlfn.RANK.EQ(G29,G:G,)-1)/(COUNTIF(G:G,">0")) -> 0 | K29: =_xlfn.IFNA(1-(_xlfn.RANK.EQ(H29,H:H,)-1)/(COUNTIF(H:H,">0")),0) -> 0 | L29: =_xlfn.IFNA(1-(_xlfn.RANK.EQ(I29,I:I,)-1)/(COUNTIF(I:I,">0")),0) -> 0 | M29: =$AG$2*J29+K29 *$AG$3+L29*$AG$4+$AG$5*E29+$AG$6*F29 -> 0.7 | N29: =OR(O29<>"",V29<>"") -> TRUE | O29: 3.57 | P29: =IFERROR(T29-O29,"") -> 0.05 | Q29: =IF(P29<>"",IF(ABS(P29)/T29>0.1,"Gny",""),"") | R29: =IF(P29<>"",ABS(P29)/T29,"") -> 0.013812155 | S29: =_xlfn.NUMBERVALUE(S28)+IF(O29,1,0) -> 15 | T29: {=IF(O29,INDEX($AP$2:$AP$21,S29,1),"")} -> 3.62 | U29: =IF(P29<>"",ABS(P29),"") -> 0.05 | V29: 53.2 | W29: =IFERROR(AA29-V29,"") -> -1.1 | X29: =IF(W29<>"",IF(ABS(W29)/AA29>0.1,"Gny",""),"") | Y29: =IF(W29<>"",ABS(W29)/AA29,"") -> 0.021113244 | Z29: =_xlfn.NUMBERVALUE(Z28)+IF(V29,1,0) -> 15 | AA29: {=IF(V29,INDEX($AK$2:$AK$20,Z29,1),"")} -> 52.1 | AB29: =IF(W29<>"",ABS(W29),"") -> 1.1 | AC29: 1 | AD29: 1
A30: CCAP | B30: =_xlfn.IFNA(INDEX(bf!B:B,MATCH(A30,bf!A:A,0),1),0) -> 0 | C30: =INDEX('اسعار الاسهم'!A:L,MATCH(A30,'اسعار الاسهم'!K:K,0),2) -> 5.2 | E30: 1 | G30: =B30/C30 -> 0 | J30: =1-(_xlfn.RANK.EQ(G30,G:G,)-1)/(COUNTIF(G:G,">0")) -> 0 | K30: =_xlfn.IFNA(1-(_xlfn.RANK.EQ(H30,H:H,)-1)/(COUNTIF(H:H,">0")),0) -> 0 | L30: =_xlfn.IFNA(1-(_xlfn.RANK.EQ(I30,I:I,)-1)/(COUNTIF(I:I,">0")),0) -> 0 | M30: =$AG$2*J30+K30 *$AG$3+L30*$AG$4+$AG$5*E30+$AG$6*F30 -> 0.7 | N30: =OR(O30<>"",V30<>"") -> FALSE | P30: =IFERROR(T30-O30,"") | Q30: =IF(P30<>"",IF(ABS(P30)/T30>0.1,"Gny",""),"") | R30: =IF(P30<>"",ABS(P30)/T30,"") | S30: =_xlfn.NUMBERVALUE(S29)+IF(O30,1,0) -> 15 | T30: {=IF(O30,INDEX($AP$2:$AP$21,S30,1),"")} | U30: =IF(P30<>"",ABS(P30),"") | W30: =IFERROR(AA30-V30,"") | X30: =IF(W30<>"",IF(ABS(W30)/AA30>0.1,"Gny",""),"") | Y30: =IF(W30<>"",ABS(W30)/AA30,"") | Z30: =_xlfn.NUMBERVALUE(Z29)+IF(V30,1,0) -> 15 | AA30: {=IF(V30,INDEX($AK$2:$AK$20,Z30,1),"")} | AB30: =IF(W30<>"",ABS(W30),"")
A31: LCSW | B31: =_xlfn.IFNA(INDEX(bf!B:B,MATCH(A31,bf!A:A,0),1),0) -> 0 | C31: =INDEX('اسعار الاسهم'!A:L,MATCH(A31,'اسعار الاسهم'!K:K,0),2) -> 26.64 | F31: 0.98 | G31: =B31/C31 -> 0 | J31: =1-(_xlfn.RANK.EQ(G31,G:G,)-1)/(COUNTIF(G:G,">0")) -> 0 | K31: =_xlfn.IFNA(1-(_xlfn.RANK.EQ(H31,H:H,)-1)/(COUNTIF(H:H,">0")),0) -> 0 | L31: =_xlfn.IFNA(1-(_xlfn.RANK.EQ(I31,I:I,)-1)/(COUNTIF(I:I,">0")),0) -> 0 | M31: =$AG$2*J31+K31 *$AG$3+L31*$AG$4+$AG$5*E31+$AG$6*F31 -> 0.686 | N31: =OR(O31<>"",V31<>"") -> FALSE | P31: =IFERROR(T31-O31,"") | Q31: =IF(P31<>"",IF(ABS(P31)/T31>0.1,"Gny",""),"") | R31: =IF(P31<>"",ABS(P31)/T31,"") | S31: =_xlfn.NUMBERVALUE(S30)+IF(O31,1,0) -> 15 | T31: {=IF(O31,INDEX($AP$2:$AP$21,S31,1),"")} | U31: =IF(P31<>"",ABS(P31),"") | W31: =IFERROR(AA31-V31,"") | X31: =IF(W31<>"",IF(ABS(W31)/AA31>0.1,"Gny",""),"") | Y31: =IF(W31<>"",ABS(W31)/AA31,"") | Z31: =_xlfn.NUMBERVALUE(Z30)+IF(V31,1,0) -> 15 | AA31: {=IF(V31,INDEX($AK$2:$AK$20,Z31,1),"")} | AB31: =IF(W31<>"",ABS(W31),"")
A32: CICH | B32: =_xlfn.IFNA(INDEX(bf!B:B,MATCH(A32,bf!A:A,0),1),0) -> 10.48 | C32: =INDEX('اسعار الاسهم'!A:L,MATCH(A32,'اسعار الاسهم'!K:K,0),2) -> 12.71 | G32: =B32/C32 -> 0.8245476 | J32: =1-(_xlfn.RANK.EQ(G32,G:G,)-1)/(COUNTIF(G:G,">0")) -> 0.85416667 | K32: =_xlfn.IFNA(1-(_xlfn.RANK.EQ(H32,H:H,)-1)/(COUNTIF(H:H,">0")),0) -> 0 | L32: =_xlfn.IFNA(1-(_xlfn.RANK.EQ(I32,I:I,)-1)/(COUNTIF(I:I,">0")),0) -> 0 | M32: =$AG$2*J32+K32 *$AG$3+L32*$AG$4+$AG$5*E32+$AG$6*F32 -> 0.68333333 | N32: =OR(O32<>"",V32<>"") -> FALSE | P32: =IFERROR(T32-O32,"") | Q32: =IF(P32<>"",IF(ABS(P32)/T32>0.1,"Gny",""),"") | R32: =IF(P32<>"",ABS(P32)/T32,"") | S32: =_xlfn.NUMBERVALUE(S31)+IF(O32,1,0) -> 15 | T32: {=IF(O32,INDEX($AP$2:$AP$21,S32,1),"")} | U32: =IF(P32<>"",ABS(P32),"") | W32: =IFERROR(AA32-V32,"") | X32: =IF(W32<>"",IF(ABS(W32)/AA32>0.1,"Gny",""),"") | Y32: =IF(W32<>"",ABS(W32)/AA32,"") | Z32: =_xlfn.NUMBERVALUE(Z31)+IF(V32,1,0) -> 15 | AA32: {=IF(V32,INDEX($AK$2:$AK$20,Z32,1),"")} | AB32: =IF(W32<>"",ABS(W32),"") | AD32: 1
A33: RACC | B33: =_xlfn.IFNA(INDEX(bf!B:B,MATCH(A33,bf!A:A,0),1),0) -> 3.68 | C33: =INDEX('اسعار الاسهم'!A:L,MATCH(A33,'اسعار الاسهم'!K:K,0),2) -> 9.7 | F33: 0.82 | G33: =B33/C33 -> 0.37938144 | J33: =1-(_xlfn.RANK.EQ(G33,G:G,)-1)/(COUNTIF(G:G,">0")) -> 0.10416667 | K33: =_xlfn.IFNA(1-(_xlfn.RANK.EQ(H33,H:H,)-1)/(COUNTIF(H:H,">0")),0) -> 0 | L33: =_xlfn.IFNA(1-(_xlfn.RANK.EQ(I33,I:I,)-1)/(COUNTIF(I:I,">0")),0) -> 0 | M33: =$AG$2*J33+K33 *$AG$3+L33*$AG$4+$AG$5*E33+$AG$6*F33 -> 0.65733333 | N33: =OR(O33<>"",V33<>"") -> FALSE | P33: =IFERROR(T33-O33,"") | Q33: =IF(P33<>"",IF(ABS(P33)/T33>0.1,"Gny",""),"") | R33: =IF(P33<>"",ABS(P33)/T33,"") | S33: =_xlfn.NUMBERVALUE(S32)+IF(O33,1,0) -> 15 | T33: {=IF(O33,INDEX($AP$2:$AP$21,S33,1),"")} | U33: =IF(P33<>"",ABS(P33),"") | W33: =IFERROR(AA33-V33,"") | X33: =IF(W33<>"",IF(ABS(W33)/AA33>0.1,"Gny",""),"") | Y33: =IF(W33<>"",ABS(W33)/AA33,"") | Z33: =_xlfn.NUMBERVALUE(Z32)+IF(V33,1,0) -> 15 | AA33: {=IF(V33,INDEX($AK$2:$AK$20,Z33,1),"")} | AB33: =IF(W33<>"",ABS(W33),"")
A34: TALM | B34: =_xlfn.IFNA(INDEX(bf!B:B,MATCH(A34,bf!A:A,0),1),0) -> 12.19 | C34: =INDEX('اسعار الاسهم'!A:L,MATCH(A34,'اسعار الاسهم'!K:K,0),2) -> 15.64 | G34: =B34/C34 -> 0.77941176 | J34: =1-(_xlfn.RANK.EQ(G34,G:G,)-1)/(COUNTIF(G:G,">0")) -> 0.79166667 | K34: =_xlfn.IFNA(1-(_xlfn.RANK.EQ(H34,H:H,)-1)/(COUNTIF(H:H,">0")),0) -> 0 | L34: =_xlfn.IFNA(1-(_xlfn.RANK.EQ(I34,I:I,)-1)/(COUNTIF(I:I,">0")),0) -> 0 | M34: =$AG$2*J34+K34 *$AG$3+L34*$AG$4+$AG$5*E34+$AG$6*F34 -> 0.63333333 | N34: =OR(O34<>"",V34<>"") -> FALSE | P34: =IFERROR(T34-O34,"") | Q34: =IF(P34<>"",IF(ABS(P34)/T34>0.1,"Gny",""),"") | R34: =IF(P34<>"",ABS(P34)/T34,"") | S34: =_xlfn.NUMBERVALUE(S33)+IF(O34,1,0) -> 15 | T34: {=IF(O34,INDEX($AP$2:$AP$21,S34,1),"")} | U34: =IF(P34<>"",ABS(P34),"") | W34: =IFERROR(AA34-V34,"") | X34: =IF(W34<>"",IF(ABS(W34)/AA34>0.1,"Gny",""),"") | Y34: =IF(W34<>"",ABS(W34)/AA34,"") | Z34: =_xlfn.NUMBERVALUE(Z33)+IF(V34,1,0) -> 15 | AA34: {=IF(V34,INDEX($AK$2:$AK$20,Z34,1),"")} | AB34: =IF(W34<>"",ABS(W34),"")
A35: ELEC | B35: =_xlfn.IFNA(INDEX(bf!B:B,MATCH(A35,bf!A:A,0),1),0) -> 0 | C35: =INDEX('اسعار الاسهم'!A:L,MATCH(A35,'اسعار الاسهم'!K:K,0),2) -> 2.1 | G35: =B35/C35 -> 0 | I35: =3.8/C35-1 -> 0.80952381 | J35: =1-(_xlfn.RANK.EQ(G35,G:G,)-1)/(COUNTIF(G:G,">0")) -> 0 | K35: =_xlfn.IFNA(1-(_xlfn.RANK.EQ(H35,H:H,)-1)/(COUNTIF(H:H,">0")),0) -> 0 | L35: =_xlfn.IFNA(1-(_xlfn.RANK.EQ(I35,I:I,)-1)/(COUNTIF(I:I,">0")),0) -> 1 | M35: =$AG$2*J35+K35 *$AG$3+L35*$AG$4+$AG$5*E35+$AG$6*F35 -> 0.6 | N35: =OR(O35<>"",V35<>"") -> FALSE | P35: =IFERROR(T35-O35,"") | Q35: =IF(P35<>"",IF(ABS(P35)/T35>0.1,"Gny",""),"") | R35: =IF(P35<>"",ABS(P35)/T35,"") | S35: =_xlfn.NUMBERVALUE(S34)+IF(O35,1,0) -> 15 | T35: {=IF(O35,INDEX($AP$2:$AP$21,S35,1),"")} | U35: =IF(P35<>"",ABS(P35),"") | W35: =IFERROR(AA35-V35,"") | X35: =IF(W35<>"",IF(ABS(W35)/AA35>0.1,"Gny",""),"") | Y35: =IF(W35<>"",ABS(W35)/AA35,"") | Z35: =_xlfn.NUMBERVALUE(Z34)+IF(V35,1,0) -> 15 | AA35: {=IF(V35,INDEX($AK$2:$AK$20,Z35,1),"")} | AB35: =IF(W35<>"",ABS(W35),"")
A36: MPCO | B36: =_xlfn.IFNA(INDEX(bf!B:B,MATCH(A36,bf!A:A,0),1),0) -> 0 | C36: =INDEX('اسعار الاسهم'!A:L,MATCH(A36,'اسعار الاسهم'!K:K,0),2) -> 1.57 | G36: =B36/C36 -> 0 | I36: =2.8/C36-1 -> 0.78343949 | J36: =1-(_xlfn.RANK.EQ(G36,G:G,)-1)/(COUNTIF(G:G,">0")) -> 0 | K36: =_xlfn.IFNA(1-(_xlfn.RANK.EQ(H36,H:H,)-1)/(COUNTIF(H:H,">0")),0) -> 0 | L36: =_xlfn.IFNA(1-(_xlfn.RANK.EQ(I36,I:I,)-1)/(COUNTIF(I:I,">0")),0) -> 0.96666667 | M36: =$AG$2*J36+K36 *$AG$3+L36*$AG$4+$AG$5*E36+$AG$6*F36 -> 0.58 | N36: =OR(O36<>"",V36<>"") -> FALSE | P36: =IFERROR(T36-O36,"") | Q36: =IF(P36<>"",IF(ABS(P36)/T36>0.1,"Gny",""),"") | R36: =IF(P36<>"",ABS(P36)/T36,"") | S36: =_xlfn.NUMBERVALUE(S35)+IF(O36,1,0) -> 15 | T36: {=IF(O36,INDEX($AP$2:$AP$21,S36,1),"")} | U36: =IF(P36<>"",ABS(P36),"") | W36: =IFERROR(AA36-V36,"") | X36: =IF(W36<>"",IF(ABS(W36)/AA36>0.1,"Gny",""),"") | Y36: =IF(W36<>"",ABS(W36)/AA36,"") | Z36: =_xlfn.NUMBERVALUE(Z35)+IF(V36,1,0) -> 15 | AA36: {=IF(V36,INDEX($AK$2:$AK$20,Z36,1),"")} | AB36: =IF(W36<>"",ABS(W36),"")
A37: VLMRA | B37: =_xlfn.IFNA(INDEX(bf!B:B,MATCH(A37,bf!A:A,0),1),0) -> 0 | C37: =INDEX('اسعار الاسهم'!A:L,MATCH(A37,'اسعار الاسهم'!K:K,0),2) -> 30.4 | G37: =B37/C37 -> 0 | H37: =42.7/C37-1 -> 0.40460526 | J37: =1-(_xlfn.RANK.EQ(G37,G:G,)-1)/(COUNTIF(G:G,">0")) -> 0 | K37: =_xlfn.IFNA(1-(_xlfn.RANK.EQ(H37,H:H,)-1)/(COUNTIF(H:H,">0")),0) -> 0.57142857 | L37: =_xlfn.IFNA(1-(_xlfn.RANK.EQ(I37,I:I,)-1)/(COUNTIF(I:I,">0")),0) -> 0 | M37: =$AG$2*J37+K37 *$AG$3+L37*$AG$4+$AG$5*E37+$AG$6*F37 -> 0.57142857 | N37: =OR(O37<>"",V37<>"") -> TRUE | O37: 3.67 | P37: =IFERROR(T37-O37,"") -> -0.22 | Q37: =IF(P37<>"",IF(ABS(P37)/T37>0.1,"Gny",""),"") | R37: =IF(P37<>"",ABS(P37)/T37,"") -> 0.063768116 | S37: =_xlfn.NUMBERVALUE(S36)+IF(O37,1,0) -> 16 | T37: {=IF(O37,INDEX($AP$2:$AP$21,S37,1),"")} -> 3.45 | U37: =IF(P37<>"",ABS(P37),"") -> 0.22 | V37: 52 | W37: =IFERROR(AA37-V37,"") -> -2.3 | X37: =IF(W37<>"",IF(ABS(W37)/AA37>0.1,"Gny",""),"") | Y37: =IF(W37<>"",ABS(W37)/AA37,"") -> 0.046277666 | Z37: =_xlfn.NUMBERVALUE(Z36)+IF(V37,1,0) -> 16 | AA37: {=IF(V37,INDEX($AK$2:$AK$20,Z37,1),"")} -> 49.7 | AB37: =IF(W37<>"",ABS(W37),"") -> 2.3 | AC37: 1
A38: ELSH | B38: =_xlfn.IFNA(INDEX(bf!B:B,MATCH(A38,bf!A:A,0),1),0) -> 5.94 | C38: =INDEX('اسعار الاسهم'!A:L,MATCH(A38,'اسعار الاسهم'!K:K,0),2) -> 8.38 | G38: =B38/C38 -> 0.70883055 | J38: =1-(_xlfn.RANK.EQ(G38,G:G,)-1)/(COUNTIF(G:G,">0")) -> 0.70833333 | K38: =_xlfn.IFNA(1-(_xlfn.RANK.EQ(H38,H:H,)-1)/(COUNTIF(H:H,">0")),0) -> 0 | L38: =_xlfn.IFNA(1-(_xlfn.RANK.EQ(I38,I:I,)-1)/(COUNTIF(I:I,">0")),0) -> 0 | M38: =$AG$2*J38+K38 *$AG$3+L38*$AG$4+$AG$5*E38+$AG$6*F38 -> 0.56666667 | N38: =OR(O38<>"",V38<>"") -> FALSE | P38: =IFERROR(T38-O38,"") | Q38: =IF(P38<>"",IF(ABS(P38)/T38>0.1,"Gny",""),"") | R38: =IF(P38<>"",ABS(P38)/T38,"") | S38: =_xlfn.NUMBERVALUE(S37)+IF(O38,1,0) -> 16 | T38: {=IF(O38,INDEX($AP$2:$AP$21,S38,1),"")} | U38: =IF(P38<>"",ABS(P38),"") | W38: =IFERROR(AA38-V38,"") | X38: =IF(W38<>"",IF(ABS(W38)/AA38>0.1,"Gny",""),"") | Y38: =IF(W38<>"",ABS(W38)/AA38,"") | Z38: =_xlfn.NUMBERVALUE(Z37)+IF(V38,1,0) -> 16 | AA38: {=IF(V38,INDEX($AK$2:$AK$20,Z38,1),"")} | AB38: =IF(W38<>"",ABS(W38),"")
A39: MEPA | B39: =_xlfn.IFNA(INDEX(bf!B:B,MATCH(A39,bf!A:A,0),1),0) -> 0.77 | C39: =INDEX('اسعار الاسهم'!A:L,MATCH(A39,'اسعار الاسهم'!K:K,0),2) -> 1.66 | G39: =B39/C39 -> 0.46385542 | I39: =2.3/C39-1 -> 0.38554217 | J39: =1-(_xlfn.RANK.EQ(G39,G:G,)-1)/(COUNTIF(G:G,">0")) -> 0.22916667 | K39: =_xlfn.IFNA(1-(_xlfn.RANK.EQ(H39,H:H,)-1)/(COUNTIF(H:H,">0")),0) -> 0 | L39: =_xlfn.IFNA(1-(_xlfn.RANK.EQ(I39,I:I,)-1)/(COUNTIF(I:I,">0")),0) -> 0.63333333 | M39: =$AG$2*J39+K39 *$AG$3+L39*$AG$4+$AG$5*E39+$AG$6*F39 -> 0.56333333 | N39: =OR(O39<>"",V39<>"") -> FALSE | P39: =IFERROR(T39-O39,"") | Q39: =IF(P39<>"",IF(ABS(P39)/T39>0.1,"Gny",""),"") | R39: =IF(P39<>"",ABS(P39)/T39,"") | S39: =_xlfn.NUMBERVALUE(S38)+IF(O39,1,0) -> 16 | T39: {=IF(O39,INDEX($AP$2:$AP$21,S39,1),"")} | U39: =IF(P39<>"",ABS(P39),"") | W39: =IFERROR(AA39-V39,"") | X39: =IF(W39<>"",IF(ABS(W39)/AA39>0.1,"Gny",""),"") | Y39: =IF(W39<>"",ABS(W39)/AA39,"") | Z39: =_xlfn.NUMBERVALUE(Z38)+IF(V39,1,0) -> 16 | AA39: {=IF(V39,INDEX($AK$2:$AK$20,Z39,1),"")} | AB39: =IF(W39<>"",ABS(W39),"")
A40: ARAB | B40: =_xlfn.IFNA(INDEX(bf!B:B,MATCH(A40,bf!A:A,0),1),0) -> 0 | C40: =INDEX('اسعار الاسهم'!A:L,MATCH(A40,'اسعار الاسهم'!K:K,0),2) -> 0.2 | G40: =B40/C40 -> 0 | I40: =0.318/C40-1 -> 0.59 | J40: =1-(_xlfn.RANK.EQ(G40,G:G,)-1)/(COUNTIF(G:G,">0")) -> 0 | K40: =_xlfn.IFNA(1-(_xlfn.RANK.EQ(H40,H:H,)-1)/(COUNTIF(H:H,">0")),0) -> 0 | L40: =_xlfn.IFNA(1-(_xlfn.RANK.EQ(I40,I:I,)-1)/(COUNTIF(I:I,">0")),0) -> 0.93333333 | M40: =$AG$2*J40+K40 *$AG$3+L40*$AG$4+$AG$5*E40+$AG$6*F40 -> 0.56 | N40: =OR(O40<>"",V40<>"") -> FALSE | P40: =IFERROR(T40-O40,"") | Q40: =IF(P40<>"",IF(ABS(P40)/T40>0.1,"Gny",""),"") | R40: =IF(P40<>"",ABS(P40)/T40,"") | S40: =_xlfn.NUMBERVALUE(S39)+IF(O40,1,0) -> 16 | T40: {=IF(O40,INDEX($AP$2:$AP$21,S40,1),"")} | U40: =IF(P40<>"",ABS(P40),"") | W40: =IFERROR(AA40-V40,"") | X40: =IF(W40<>"",IF(ABS(W40)/AA40>0.1,"Gny",""),"") | Y40: =IF(W40<>"",ABS(W40)/AA40,"") | Z40: =_xlfn.NUMBERVALUE(Z39)+IF(V40,1,0) -> 16 | AA40: {=IF(V40,INDEX($AK$2:$AK$20,Z40,1),"")} | AB40: =IF(W40<>"",ABS(W40),"")
...

Sheet ra2eb egabia
A1: sahm | B1: egaby | C1: current | D1: ba2y | F1: rank | G1: sahm | H1: 45764 | I1: توزيعات | J1: today | K1: performance
A2: ebsc | B2: 1.29 | C2: =INDEX('اسعار الاسهم'!A:B,MATCH(A2,'اسعار الاسهم'!K:K,0),2) -> 1.66 | D2: =1-C2/B2 -> -0.28682171 | F2: 5 | G2: hdbk | H2: 50.79 | I2: =5+8 -> 13 | J2: =I2+INDEX('اسعار الاسهم'!A:B,MATCH(G2,'اسعار الاسهم'!K:K,0),2) -> 156.45 | K2: =J2/H2-1 -> 2.0803308
A3: swdy | B3: 79.25 | C3: =INDEX('اسعار الاسهم'!A:B,MATCH(A3,'اسعار الاسهم'!K:K,0),2) -> 87.9 | D3: =1-C3/B3 -> -0.10914826 | F3: 1 | G3: adib | H3: =41.46/2/1.25 -> 16.584 | J3: =I3+INDEX('اسعار الاسهم'!A:B,MATCH(G3,'اسعار الاسهم'!K:K,0),2) -> 46.1 | K3: =J3/H3-1 -> 1.7797877
A4: zmid | B4: 3.35 | C4: =INDEX('اسعار الاسهم'!A:B,MATCH(A4,'اسعار الاسهم'!K:K,0),2) -> 5.86 | D4: =1-C4/B4 -> -0.74925373 | F4: 2 | G4: qnbe | H4: 28.31 | I4: =2+1.5 -> 3.5 | J4: =I4+INDEX('اسعار الاسهم'!A:B,MATCH(G4,'اسعار الاسهم'!K:K,0),2) -> 56.89 | K4: =J4/H4-1 -> 1.0095373
A5: comi | B5: 80.31 | C5: =INDEX('اسعار الاسهم'!A:B,MATCH(A5,'اسعار الاسهم'!K:K,0),2) -> 132.35 | D5: =1-C5/B5 -> -0.64798904 | F5: 4 | G5: efid | H5: =27.3/2 -> 13.65 | I5: =1.142/2 -> 0.571 | J5: =I5+INDEX('اسعار الاسهم'!A:B,MATCH(G5,'اسعار الاسهم'!K:K,0),2) -> 28.491 | K5: =J5/H5-1 -> 1.0872527
A6: mich | B6: 28.13 | C6: =INDEX('اسعار الاسهم'!A:B,MATCH(A6,'اسعار الاسهم'!K:K,0),2) -> 35.5 | D6: =1-C6/B6 -> -0.26199787 | F6: 3 | G6: engc | H6: 23.35 | I6: 1.25 | J6: =I6+INDEX('اسعار الاسهم'!A:B,MATCH(G6,'اسعار الاسهم'!K:K,0),2) -> 34.01 | K6: =J6/H6-1 -> 0.45653105
A7: afdi | B7: 28.82 | C7: =INDEX('اسعار الاسهم'!A:B,MATCH(A7,'اسعار الاسهم'!K:K,0),2) -> 41.67 | D7: =1-C7/B7 -> -0.44587092 | F7: 6 | G7: olfi | H7: 16.72 | I7: 1.75 | J7: =I7+INDEX('اسعار الاسهم'!A:B,MATCH(G7,'اسعار الاسهم'!K:K,0),2) -> 22.9 | K7: =J7/H7-1 -> 0.36961722
A8: arab | B8: 0.39 | C8: =INDEX('اسعار الاسهم'!A:B,MATCH(A8,'اسعار الاسهم'!K:K,0),2) -> 0.2 | D8: =1-C8/B8 -> 0.48717949 | F8: 7 | G8: orhd | H8: 22.94 | I8: 0.384346 | J8: =I8+INDEX('اسعار الاسهم'!A:B,MATCH(G8,'اسعار الاسهم'!K:K,0),2) -> 34.934346 | K8: =J8/H8-1 -> 0.52285728
A9: fwry | B9: 8.57 | C9: =INDEX('اسعار الاسهم'!A:B,MATCH(A9,'اسعار الاسهم'!K:K,0),2) -> 19.32 | D9: =1-C9/B9 -> -1.2543757 | F9: 8 | G9: VLMRA | H9: =29.18/1.05046 -> 27.778307 | I9: =0.035*50/1.05046+0.045*50 -> 3.9159368 | J9: =I9+INDEX('اسعار الاسهم'!A:B,MATCH(G9,'اسعار الاسهم'!K:K,0),2) -> 34.315937 | K9: =J9/H9-1 -> 0.23535021
A10: efih | B10: 18.02 | C10: =INDEX('اسعار الاسهم'!A:B,MATCH(A10,'اسعار الاسهم'!K:K,0),2) -> 21.76 | D10: =1-C10/B10 -> -0.20754717
A11: tmgh | B11: 54.74 | C11: =INDEX('اسعار الاسهم'!A:B,MATCH(A11,'اسعار الاسهم'!K:K,0),2) -> 99.48 | D11: =1-C11/B11 -> -0.81731823
A12: phgc | B12: 1.2 | C12: =INDEX('اسعار الاسهم'!A:B,MATCH(A12,'اسعار الاسهم'!K:K,0),2) -> 0.09 | D12: =1-C12/B12 -> 0.925
A13: GGRN | B13: 1.89 | C13: =INDEX('اسعار الاسهم'!A:B,MATCH(A13,'اسعار الاسهم'!K:K,0),2) -> 1.42 | D13: =1-C13/B13 -> 0.24867725
C14: =INDEX('اسعار الاسهم'!A:B,MATCH(A14,'اسعار الاسهم'!K:K,0),2) -> #N/A | D14: =1-C14/B14 -> #N/A
C15: =INDEX('اسعار الاسهم'!A:B,MATCH(A15,'اسعار الاسهم'!K:K,0),2) -> #N/A | D15: =1-C15/B15 -> #N/A
C16: =INDEX('اسعار الاسهم'!A:B,MATCH(A16,'اسعار الاسهم'!K:K,0),2) -> #N/A | D16: =1-C16/B16 -> #N/A
C17: =INDEX('اسعار الاسهم'!A:B,MATCH(A17,'اسعار الاسهم'!K:K,0),2) -> #N/A | D17: =1-C17/B17 -> #N/A

Sheet ra2eb 2
B1: curr | C1: next
A2: hrho | B2: 500 | C2: {=IF(B2<>"",INDEX(H:H,MATCH(B2,H:H)+1),"")} -> 900 | H2: 500
A3: atqa | B3: 500 | C3: {=IF(B3<>"",INDEX(H:H,MATCH(B3,H:H)+1),"")} -> 900 | H3: 900
A4: zmid | B4: 500 | C4: {=IF(B4<>"",INDEX(H:H,MATCH(B4,H:H)+1),"")} -> 900 | H4: 1600
A5: ismq | B5: 500 | C5: {=IF(B5<>"",INDEX(H:H,MATCH(B5,H:H)+1),"")} -> 900 | H5: 2800
A6: ocdi | B6: 500 | C6: {=IF(B6<>"",INDEX(H:H,MATCH(B6,H:H)+1),"")} -> 900 | E6: safety | H6: 4800
A7: amer | B7: 500 | C7: {=IF(B7<>"",INDEX(H:H,MATCH(B7,H:H)+1),"")} -> 900 | E7: =SUM(C2:C28)/4 -> 1575 | H7: 8000
A8: heli | B8: 500 | C8: {=IF(B8<>"",INDEX(H:H,MATCH(B8,H:H)+1),"")} -> 900 | H8: 12800
C9: {=IF(B9<>"",INDEX(H:H,MATCH(B9,H:H)+1),"")} | H9: 25600
C10: {=IF(B10<>"",INDEX(H:H,MATCH(B10,H:H)+1),"")} | H10: 25600
C11: {=IF(B11<>"",INDEX(H:H,MATCH(B11,H:H)+1),"")}
C12: {=IF(B12<>"",INDEX(H:H,MATCH(B12,H:H)+1),"")}
C13: {=IF(B13<>"",INDEX(H:H,MATCH(B13,H:H)+1),"")}
C14: {=IF(B14<>"",INDEX(H:H,MATCH(B14,H:H)+1),"")}
C15: {=IF(B15<>"",INDEX(H:H,MATCH(B15,H:H)+1),"")}
C16: {=IF(B16<>"",INDEX(H:H,MATCH(B16,H:H)+1),"")}
C17: {=IF(B17<>"",INDEX(H:H,MATCH(B17,H:H)+1),"")}
C18: {=IF(B18<>"",INDEX(H:H,MATCH(B18,H:H)+1),"")}

Sheet evaluate ostoul
A1: num | B1: sahm | C1: before end of | D1: buy | E1: target | F1: loss | G1: current | H1: result | I1: up | J1: down | K1: range | L1: ratio | M1: near | N1: count active | O1: done scenario | P1: done num | Q1: result
A2: 362 | B2: tmgh | C2: 45652 | D2: 56.75 | E2: 61.6 | F2: 55.5 | G2: =INDEX('اسعار الاسهم'!A:B,MATCH(B2,'اسعار الاسهم'!K:K,0),2) -> 99.48 | H2: =IF(O2="", G2/D2-1,"") -> 0.75295154 | I2: =IF(O2="", E2/G2-1,"") -> -0.38078006 | J2: =IF(O2="", 1-F2/G2,"") -> 0.44209891 | K2: =E2/F2-1 -> 0.10990991 | L2: =IF( P2="",I2/J2,"") -> -0.86130059 | M2: =IF(O2="",IF(I2<J2,"up","down"),"") -> up | N2: =COUNTIFS(B:B,B2,O:O,"") -> 5 | Q2: =IF(NOT( P2=""),IF(O2=1,E2/D2-1,F2/D2-1),"") | S2: =AVERAGE(Q:Q) -> 0.00065718838 | T2: =MAX(P:P) -> 204
A3: 363 | B3: snfc | C3: 45652 | D3: 5.58 | E3: 6.15 | F3: 5.25 | G3: =INDEX('اسعار الاسهم'!A:B,MATCH(B3,'اسعار الاسهم'!K:K,0),2) -> 12.29 | H3: =IF(O3="", G3/D3-1,"") -> 1.202509 | I3: =IF(O3="", E3/G3-1,"") -> -0.49959317 | J3: =IF(O3="", 1-F3/G3,"") -> 0.57282343 | K3: =E3/F3-1 -> 0.17142857 | L3: =IF( P3="",I3/J3,"") -> -0.87215909 | M3: =IF(O3="",IF(I3<J3,"up","down"),"") -> up | N3: =COUNTIFS(B:B,B3,O:O,"") -> 2 | Q3: =IF(NOT( P3=""),IF(O3=1,E3/D3-1,F3/D3-1),"")
A4: 364 | B4: clho | C4: 45652 | D4: 7.94 | E4: 9.35 | F4: 7.55 | G4: =INDEX('اسعار الاسهم'!A:B,MATCH(B4,'اسعار الاسهم'!K:K,0),2) -> 15.19 | H4: =IF(O4="", G4/D4-1,"") -> 0.91309824 | I4: =IF(O4="", E4/G4-1,"") -> -0.38446346 | J4: =IF(O4="", 1-F4/G4,"") -> 0.50296248 | K4: =E4/F4-1 -> 0.2384106 | L4: =IF( P4="",I4/J4,"") -> -0.76439791 | M4: =IF(O4="",IF(I4<J4,"up","down"),"") -> up | N4: =COUNTIFS(B:B,B4,O:O,"") -> 2 | Q4: =IF(NOT( P4=""),IF(O4=1,E4/D4-1,F4/D4-1),"")
A5: 365 | B5: phdc | C5: 45652 | D5: 6.26 | E5: 6.9 | F5: 5.9 | G5: =INDEX('اسعار الاسهم'!A:B,MATCH(B5,'اسعار الاسهم'!K:K,0),2) -> 13.61 | H5: =IF(O5="", G5/D5-1,"") -> 1.1741214 | I5: =IF(O5="", E5/G5-1,"") -> -0.49301984 | J5: =IF(O5="", 1-F5/G5,"") -> 0.56649522 | K5: =E5/F5-1 -> 0.16949153 | L5: =IF( P5="",I5/J5,"") -> -0.87029831 | M5: =IF(O5="",IF(I5<J5,"up","down"),"") -> up | N5: =COUNTIFS(B:B,B5,O:O,"") -> 4 | Q5: =IF(NOT( P5=""),IF(O5=1,E5/D5-1,F5/D5-1),"")
A6: 366 | B6: kabo | C6: 45652 | D6: 3.82 | E6: 4.15 | F6: 3.5 | G6: =INDEX('اسعار الاسهم'!A:B,MATCH(B6,'اسعار الاسهم'!K:K,0),2) -> 6.11 | H6: =IF(O6="", G6/D6-1,"") -> 0.59947644 | I6: =IF(O6="", E6/G6-1,"") -> -0.3207856 | J6: =IF(O6="", 1-F6/G6,"") -> 0.42716858 | K6: =E6/F6-1 -> 0.18571429 | L6: =IF( P6="",I6/J6,"") -> -0.75095785 | M6: =IF(O6="",IF(I6<J6,"up","down"),"") -> up | N6: =COUNTIFS(B:B,B6,O:O,"") -> 1 | Q6: =IF(NOT( P6=""),IF(O6=1,E6/D6-1,F6/D6-1),"")
A7: 263 | B7: raya | C7: 45638 | D7: 3.52 | E7: 4 | F7: 3.15 | G7: =INDEX('اسعار الاسهم'!A:B,MATCH(B7,'اسعار الاسهم'!K:K,0),2) -> 7.15 | H7: =IF(O7="", G7/D7-1,"") | I7: =IF(O7="", E7/G7-1,"") | J7: =IF(O7="", 1-F7/G7,"") | K7: =E7/F7-1 -> 0.26984127 | L7: =IF( P7="",I7/J7,"") | M7: =IF(O7="",IF(I7<J7,"up","down"),"") | N7: =COUNTIFS(B:B,B7,O:O,"") -> 3 | O7: 0 | P7: 202 | Q7: =IF(NOT( P7=""),IF(O7=1,E7/D7-1,F7/D7-1),"") -> -0.10511364
A8: 367 | B8: comi | C8: 45652 | D8: 81.6 | E8: 84 | F8: 80 | G8: =INDEX('اسعار الاسهم'!A:B,MATCH(B8,'اسعار الاسهم'!K:K,0),2) -> 132.35 | H8: =IF(O8="", G8/D8-1,"") -> 0.62193627 | I8: =IF(O8="", E8/G8-1,"") -> -0.36531923 | J8: =IF(O8="", 1-F8/G8,"") -> 0.39554212 | K8: =E8/F8-1 -> 0.05 | L8: =IF( P8="",I8/J8,"") -> -0.92359121 | M8: =IF(O8="",IF(I8<J8,"up","down"),"") -> up | N8: =COUNTIFS(B:B,B8,O:O,"") -> 5 | Q8: =IF(NOT( P8=""),IF(O8=1,E8/D8-1,F8/D8-1),"")
A9: 305 | B9: raya | C9: 45644 | D9: 3.43 | E9: 4.07 | F9: 3.12 | G9: =INDEX('اسعار الاسهم'!A:B,MATCH(B9,'اسعار الاسهم'!K:K,0),2) -> 7.15 | H9: =IF(O9="", G9/D9-1,"") | I9: =IF(O9="", E9/G9-1,"") | J9: =IF(O9="", 1-F9/G9,"") | K9: =E9/F9-1 -> 0.30448718 | L9: =IF( P9="",I9/J9,"") | M9: =IF(O9="",IF(I9<J9,"up","down"),"") | N9: =COUNTIFS(B:B,B9,O:O,"") -> 3 | O9: 0 | P9: 204 | Q9: =IF(NOT( P9=""),IF(O9=1,E9/D9-1,F9/D9-1),"") -> -0.090379009
A10: 368 | B10: oras | C10: 45652 | D10: 281.63 | E10: 300 | F10: 275 | G10: =INDEX('اسعار الاسهم'!A:B,MATCH(B10,'اسعار الاسهم'!K:K,0),2) -> 708.01 | H10: =IF(O10="", G10/D10-1,"") -> 1.5139722 | I10: =IF(O10="", E10/G10-1,"") -> -0.57627717 | J10: =IF(O10="", 1-F10/G10,"") -> 0.61158741 | K10: =E10/F10-1 -> 0.090909091 | L10: =IF( P10="",I10/J10,"") -> -0.94226461 | M10: =IF(O10="",IF(I10<J10,"up","down"),"") -> up | N10: =COUNTIFS(B:B,B10,O:O,"") -> 1 | Q10: =IF(NOT( P10=""),IF(O10=1,E10/D10-1,F10/D10-1),"")
A11: 369 | B11: olfi | C11: 45652 | D11: 17.62 | E11: 20.5 | F11: 16.8 | G11: =INDEX('اسعار الاسهم'!A:B,MATCH(B11,'اسعار الاسهم'!K:K,0),2) -> 21.15 | H11: =IF(O11="", G11/D11-1,"") -> 0.20034052 | I11: =IF(O11="", E11/G11-1,"") -> -0.030732861 | J11: =IF(O11="", 1-F11/G11,"") -> 0.20567376 | K11: =E11/F11-1 -> 0.2202381 | L11: =IF( P11="",I11/J11,"") -> -0.14942529 | M11: =IF(O11="",IF(I11<J11,"up","down"),"") -> up | N11: =COUNTIFS(B:B,B11,O:O,"") -> 2 | Q11: =IF(NOT( P11=""),IF(O11=1,E11/D11-1,F11/D11-1),"")
A12: 352 | B12: svce | C12: 45651 | D12: 3.31 | E12: 3.65 | F12: 3.1 | G12: =INDEX('اسعار الاسهم'!A:B,MATCH(B12,'اسعار الاسهم'!K:K,0),2) -> 9.3 | H12: =IF(O12="", G12/D12-1,"") -> 1.8096677 | I12: =IF(O12="", E12/G12-1,"") -> -0.60752688 | J12: =IF(O12="", 1-F12/G12,"") -> 0.66666667 | K12: =E12/F12-1 -> 0.17741935 | L12: =IF( P12="",I12/J12,"") -> -0.91129032 | M12: =IF(O12="",IF(I12<J12,"up","down"),"") -> up | N12: =COUNTIFS(B:B,B12,O:O,"") -> 3 | Q12: =IF(NOT( P12=""),IF(O12=1,E12/D12-1,F12/D12-1),"")
A13: 353 | B13: etrs | C13: 45651 | D13: 5.75 | E13: 6.65 | F13: 5.25 | G13: =INDEX('اسعار الاسهم'!A:B,MATCH(B13,'اسعار الاسهم'!K:K,0),2) -> 7.59 | H13: =IF(O13="", G13/D13-1,"") -> 0.32 | I13: =IF(O13="", E13/G13-1,"") -> -0.12384717 | J13: =IF(O13="", 1-F13/G13,"") -> 0.3083004 | K13: =E13/F13-1 -> 0.26666667 | L13: =IF( P13="",I13/J13,"") -> -0.4017094 | M13: =IF(O13="",IF(I13<J13,"up","down"),"") -> up | N13: =COUNTIFS(B:B,B13,O:O,"") -> 3 | Q13: =IF(NOT( P13=""),IF(O13=1,E13/D13-1,F13/D13-1),"")
A14: 354 | B14: masr | C14: 45651 | D14: 3.86 | E14: 4.2 | F14: 3.8 | G14: =INDEX('اسعار الاسهم'!A:B,MATCH(B14,'اسعار الاسهم'!K:K,0),2) -> 6.79 | H14: =IF(O14="", G14/D14-1,"") -> 0.75906736 | I14: =IF(O14="", E14/G14-1,"") -> -0.3814433 | J14: =IF(O14="", 1-F14/G14,"") -> 0.44035346 | K14: =E14/F14-1 -> 0.10526316 | L14: =IF( P14="",I14/J14,"") -> -0.86622074 | M14: =IF(O14="",IF(I14<J14,"up","down"),"") -> up | N14: =COUNTIFS(B:B,B14,O:O,"") -> 4 | Q14: =IF(NOT( P14=""),IF(O14=1,E14/D14-1,F14/D14-1),"")
A15: 355 | B15: svce | C15: 45651 | D15: 3.31 | E15: 3.6 | F15: 3.07 | G15: =INDEX('اسعار الاسهم'!A:B,MATCH(B15,'اسعار الاسهم'!K:K,0),2) -> 9.3 | H15: =IF(O15="", G15/D15-1,"") -> 1.8096677 | I15: =IF(O15="", E15/G15-1,"") -> -0.61290323 | J15: =IF(O15="", 1-F15/G15,"") -> 0.66989247 | K15: =E15/F15-1 -> 0.17263844 | L15: =IF( P15="",I15/J15,"") -> -0.91492777 | M15: =IF(O15="",IF(I15<J15,"up","down"),"") -> up | N15: =COUNTIFS(B:B,B15,O:O,"") -> 3 | Q15: =IF(NOT( P15=""),IF(O15=1,E15/D15-1,F15/D15-1),"")
A16: 356 | B16: etrs | C16: 45651 | D16: 5.75 | E16: 6.1 | F16: 5.3 | G16: =INDEX('اسعار الاسهم'!A:B,MATCH(B16,'اسعار الاسهم'!K:K,0),2) -> 7.59 | H16: =IF(O16="", G16/D16-1,"") -> 0.32 | I16: =IF(O16="", E16/G16-1,"") -> -0.19631094 | J16: =IF(O16="", 1-F16/G16,"") -> 0.30171278 | K16: =E16/F16-1 -> 0.1509434 | L16: =IF( P16="",I16/J16,"") -> -0.65065502 | M16: =IF(O16="",IF(I16<J16,"up","down"),"") -> up | N16: =COUNTIFS(B:B,B16,O:O,"") -> 3 | Q16: =IF(NOT( P16=""),IF(O16=1,E16/D16-1,F16/D16-1),"")
A17: 357 | B17: eppk | C17: 45651 | D17: 10 | E17: 11.5 | F17: 8.7 | G17: =INDEX('اسعار الاسهم'!A:B,MATCH(B17,'اسعار الاسهم'!K:K,0),2) -> 12.63 | H17: =IF(O17="", G17/D17-1,"") -> 0.263 | I17: =IF(O17="", E17/G17-1,"") -> -0.089469517 | J17: =IF(O17="", 1-F17/G17,"") -> 0.3111639 | K17: =E17/F17-1 -> 0.32183908 | L17: =IF( P17="",I17/J17,"") -> -0.28753181 | M17: =IF(O17="",IF(I17<J17,"up","down"),"") -> up | N17: =COUNTIFS(B:B,B17,O:O,"") -> 1 | Q17: =IF(NOT( P17=""),IF(O17=1,E17/D17-1,F17/D17-1),"")
A18: 358 | B18: masr | C18: 45651 | D18: 3.9 | E18: 4.18 | F18: 3.8 | G18: =INDEX('اسعار الاسهم'!A:B,MATCH(B18,'اسعار الاسهم'!K:K,0),2) -> 6.79 | H18: =IF(O18="", G18/D18-1,"") -> 0.74102564 | I18: =IF(O18="", E18/G18-1,"") -> -0.38438881 | J18: =IF(O18="", 1-F18/G18,"") -> 0.44035346 | K18: =E18/F18-1 -> 0.1 | L18: =IF( P18="",I18/J18,"") -> -0.8729097 | M18: =IF(O18="",IF(I18<J18,"up","down"),"") -> up | N18: =COUNTIFS(B:B,B18,O:O,"") -> 4 | Q18: =IF(NOT( P18=""),IF(O18=1,E18/D18-1,F18/D18-1),"")
A19: 359 | B19: rrei | C19: 45651 | D19: 1.7 | E19: 2.02 | F19: 1.59 | G19: =INDEX('اسعار الاسهم'!A:B,MATCH(B19,'اسعار الاسهم'!K:K,0),2) -> 3.38 | H19: =IF(O19="", G19/D19-1,"") -> 0.98823529 | I19: =IF(O19="", E19/G19-1,"") -> -0.40236686 | J19: =IF(O19="", 1-F19/G19,"") -> 0.5295858 | K19: =E19/F19-1 -> 0.27044025 | L19: =IF( P19="",I19/J19,"") -> -0.75977654 | M19: =IF(O19="",IF(I19<J19,"up","down"),"") -> up | N19: =COUNTIFS(B:B,B19,O:O,"") -> 2 | Q19: =IF(NOT( P19=""),IF(O19=1,E19/D19-1,F19/D19-1),"")
A20: 360 | B20: amia | C20: 45651 | D20: 2.55 | E20: 2.75 | F20: 2.42 | G20: =INDEX('اسعار الاسهم'!A:B,MATCH(B20,'اسعار الاسهم'!K:K,0),2) -> 8.7 | H20: =IF(O20="", G20/D20-1,"") -> 2.4117647 | I20: =IF(O20="", E20/G20-1,"") -> -0.68390805 | J20: =IF(O20="", 1-F20/G20,"") -> 0.72183908 | K20: =E20/F20-1 -> 0.13636364 | L20: =IF( P20="",I20/J20,"") -> -0.94745223 | M20: =IF(O20="",IF(I20<J20,"up","down"),"") -> up | N20: =COUNTIFS(B:B,B20,O:O,"") -> 1 | Q20: =IF(NOT( P20=""),IF(O20=1,E20/D20-1,F20/D20-1),"")
